Workbook

Sheet REGLAS - PUNTOS
C2: Ptos | D2: Qty | E2: Max | F2: Max | H2: Penalidades
A3: Fase de Grupos | B3: Ganador | C3: 1 | D3: 72 | E3: {=D3*C3} -> 72 | F3: {=SUM(E3:E5)} -> 176 | H3: Revelación se queda en grupos | I3: -20
B4: Resultado exacto | C4: 1 | D4: 72 | E4: {=D4*C4} -> 72 | H4: Campeón no llega a 4tos | I4: -20
B5: 16vos | C5: 1 | D5: 32 | E5: {=D5*C5} -> 32 | H5: Peor pasa grupos | I5: -10
A6: Fase Playoffs | B6: 8vos | C6: 3 | D6: 16 | E6: {=D6*C6} -> 48 | F6: {=SUM(E6:E11)} -> 191 | H6: Decepción llega a Semis | I6: -20
B7: 4tos | C7: 6 | D7: 8 | E7: {=D7*C7} -> 48
B8: semis | C8: 10 | D8: 4 | E8: {=D8*C8} -> 40
B9: Final | C9: 15 | D9: 2 | E9: {=D9*C9} -> 30 | H9: Habrá Jugadores 4 ganadores, con 4 premios
B10: 3ero | C10: 5 | D10: 1 | E10: {=D10*C10} -> 5 | H10: 1er puesto general
B11: Campeón | C11: 20 | D11: 1 | E11: {=D11*C11} -> 20 | H11: 2do puesto general
A12: Puntos Extra | B12: Figura | C12: 12 | D12: 1 | E12: {=D12*C12} -> 12 | F12: {=SUM(E12:E17)} -> 64 | H12: 3er puesto general
B13: Goleador | C13: 12 | D13: 1 | E13: {=D13*C13} -> 12 | H13: Mejor en Resultados Grupos
B14: Revelación | C14: 12 | D14: 1 | E14: {=D14*C14} -> 12
B15: Decepción | C15: 12 | D15: 1 | E15: {=D15*C15} -> 12 | H15: El premio del 3er puesto será equivalente al del Mejor en Resultados Grupos
B16: Mejor 1era Fase | C16: 8 | D16: 1 | E16: {=D16*C16} -> 8 | H16: Si el Mejor en Resultados Grupos, sale entre los 3 primeros en la general; entonces el premio de Mejor en Resultados Grupos será adjudicado al siguiente (que no sea de los 3 primeros en la general).
B17: Peor Equipo | C17: 8 | D17: 1 | E17: {=D17*C17} -> 8
E18: {=SUM(E3:E17)} -> 431
A20: Revelación y Decepción
A21: Hay 4 clases de equipos, según su historia, importancia, vigencia y Ranking FIFA. Abajo podrán ver en qué clase entra cada equipo.
A23: El PEOR de los equipos CLASE 1, es automáticamente calificado como Decepción. (A su vez, existen 3 equipos clase 1´; si hay "empate" entre un 1´y un 1, el Clase 1 será decepción)
A25: Los equipos clase 2, 3 y 4 podrán ser Revelación.
A26: Un clase 2 solo puede ser revelación si llega a Semis.
A27: Un clase 3 sólo puede ser revelación si llega a 4tos.
A28: Un clase 4 sólo puede ser revelación si pasa de grupos.
A29: El que haya llegado más lejos de los equipos clase 2, 3 o 4; será la Revelación.
A30: En caso que lleguen a misma ronda, se valorará mejor a los equipos de peor clase. Dentro de una misma clase, se desempata por puntos/goles logrados según la tabla general.
A31: El último criterio de desempate para la tabla general (Total Results) será el Ranking FIFA según 1/4/2026 (el de peor ranking queda más alto).
A32: Puede darse que NO HAYA equipo revelación.
A35: Ranking FIFA | B35: País | C35: Clase | D35: Class 1´
A36: {=_xlfn.XLOOKUP(B36,'Ranking FIFA'!B1:B102,'Ranking FIFA'!A1:A102,"--",0)} -> 1 | B36: Francia | C36: 1 | D36: 1
A37: {=_xlfn.XLOOKUP(B37,'Ranking FIFA'!B1:B102,'Ranking FIFA'!A1:A102,"--",0)} -> 2 | B37: España | C37: 1 | D37: 1
A38: {=_xlfn.XLOOKUP(B38,'Ranking FIFA'!B1:B102,'Ranking FIFA'!A1:A102,"--",0)} -> 3 | B38: Argentina | C38: 1 | D38: 1
A39: {=_xlfn.XLOOKUP(B39,'Ranking FIFA'!B1:B102,'Ranking FIFA'!A1:A102,"--",0)} -> 4 | B39: Inglaterra | C39: 1 | D39: 1
A40: {=_xlfn.XLOOKUP(B40,'Ranking FIFA'!B1:B102,'Ranking FIFA'!A1:A102,"--",0)} -> 5 | B40: Portugal | C40: 1 | D40: 1
A41: {=_xlfn.XLOOKUP(B41,'Ranking FIFA'!B1:B102,'Ranking FIFA'!A1:A102,"--",0)} -> 6 | B41: Brasil | C41: 1 | D41: 1
A42: {=_xlfn.XLOOKUP(B42,'Ranking FIFA'!B1:B102,'Ranking FIFA'!A1:A102,"--",0)} -> 7 | B42: Paises Bajos | C42: 1 | D42: 1
A43: {=_xlfn.XLOOKUP(B43,'Ranking FIFA'!B1:B102,'Ranking FIFA'!A1:A102,"--",0)} -> 9 | B43: Belgica | C43: 1 | D43: 2
A44: {=_xlfn.XLOOKUP(B44,'Ranking FIFA'!B1:B102,'Ranking FIFA'!A1:A102,"--",0)} -> 10 | B44: Alemania | C44: 1 | D44: 1
A45: {=_xlfn.XLOOKUP(B45,'Ranking FIFA'!B1:B102,'Ranking FIFA'!A1:A102,"--",0)} -> 11 | B45: Croacia | C45: 1 | D45: 2
A46: {=_xlfn.XLOOKUP(B46,'Ranking FIFA'!B1:B102,'Ranking FIFA'!A1:A102,"--",0)} -> 17 | B46: Uruguay | C46: 1 | D46: 2
...

Sheet Groups Stage
BF1: {=IF(BA3>1,AZ3,IF(BA4>1,AZ4,IF(BA5>1,AZ5,IF(BA6>1,AZ6,"-"))))} -> 4 | BW1: 10 | BZ1: {=IF(BC3>1,BB3,IF(BC4>1,BB4,IF(BC5>1,BB5,IF(BC6>1,BB6,"-"))))} -> - | CQ1: 10 | CS1: TOTAL | CV1: TERCEROS | CW1: Clasificó? | CX1: Elección
A2: Partido | B2: Fecha | C2: Sede | E2: Grupo A | J2: G | K2: E | L2: E | M2: P | O2: {=E2} -> Grupo A | P2: G | Q2: E | R2: P | S2: Dif | T2: G+ | U2: G- | V2: Ptos | Y2: Grupo A | AA2: J | AB2: G | AC2: E | AD2: P | AE2: Dif | AF2: G+ | AG2: G- | AH2: Ptos | AL2: Ptos | AM2: check | AY2: Empate 1 | AZ2: Ptos | BA2: Empate? | BL2: J | BM2: G | BN2: E | BO2: P | BP2: Dif | BQ2: G+ | BR2: G- | BS2: Ptos | BT2: Extra | BV2: Orden | BW2: Extra | CF2: J | CG2: G | CH2: E | CI2: P | CJ2: Dif | CK2: G+ | CL2: G- | CM2: Ptos | CN2: Extra | CP2: Orden | CQ2: Extra | CS2: {=SUMIF(AA1:AA108,3)} -> 144 | CV2: {='Mejores 3eros'!AP2} -> Repubilca Checa | CW2: {=_xlfn.XLOOKUP(CV2,'Mejores 3eros'!$BD$2:$BD$13,'Mejores 3eros'!$BG$2:$BG$13,"-",0)} -> IN | CX2: -
A3: GA1 | B3: 46184 | E3: Mexico | F3: 2 | G3: 0 | H3: Sudafrica | J3: {=IF(OR(ISBLANK(F3),ISBLANK(G3)),"",IF(F3>G3,E3,IF(G3>F3,H3,"")))} -> Mexico | K3: {=IF(OR(ISBLANK(F3),ISBLANK(G3)),"",IF(F3=G3,E3,""))} | L3: {=IF(OR(ISBLANK(F3),ISBLANK(G3)),"",IF(F3=G3,H3,""))} | M3: {=IF(OR(ISBLANK(F3),ISBLANK(G3)),"",IF(F3<G3,E3,IF(G3<F3,H3,"")))} -> Sudafrica | O3: {=E3} -> Mexico | P3: {=COUNTIF(J3:J8,"="&$O3)} -> 3 | Q3: {=COUNTIF(K3:L8,"="&$O3)} -> 0 | R3: {=COUNTIF(M3:M8,"="&$O3)} -> 0 | S3: {=T3-U3} -> 4 | T3: {=SUMIF(E3:E8,$O3,F3:F8)+SUMIF(H3:H8,$O3,G3:G8)} -> 5 | U3: {=SUMIF(E3:E8,$O3,G3:G8)+SUMIF(H3:H8,$O3,F3:F8)} -> 1 | V3: {=P3*3+Q3*1+BT3+CN3+S3/1000+T3/10000+AV3/1000000+ROW()/10000000} -> 9.0045003 | W3: {=O3} -> Mexico | Y3: {=CONCATENATE("1",RIGHT(E2,1))} -> 1A | Z3: {=VLOOKUP(AL3,V3:W6,2,FALSE)} -> Mexico | AA3: {=SUM(AB3:AD3)} -> 3 | AB3: {=VLOOKUP($Z3,$O$3:$U$6,COLUMN()-26,FALSE)} -> 3 | AC3: {=VLOOKUP($Z3,$O$3:$U$6,COLUMN()-26,FALSE)} -> 0 | AD3: {=VLOOKUP($Z3,$O$3:$U$6,COLUMN()-26,FALSE)} -> 0 | AE3: {=VLOOKUP($Z3,$O$3:$U$6,COLUMN()-26,FALSE)} -> 4 | AF3: {=VLOOKUP($Z3,$O$3:$U$6,COLUMN()-26,FALSE)} -> 5 | AG3: {=VLOOKUP($Z3,$O$3:$U$6,COLUMN()-26,FALSE)} -> 1 | AH3: {=VLOOKUP($Z3,$O$3:$V$6,COLUMN()-26,FALSE)} -> 9.0045003 | AL3: {=LARGE(V3:V6,1)} -> 9.0045003 | AM3: {=(AH3-AL3)*100000000000000000000} -> 0 | AP3: {=O3} -> Mexico | AQ3: {=P3*3+Q3*1+BT3+CN3+S3/1000+T3/10000} -> 9.0045 | AR3: {=IF(OR(AQ3=AQ4,AQ3=AQ5,AQ3=AQ6),1)} -> FALSE | AS3: {=AV3} -> 0 | AT3: {=IF(AND(AM7="si",OR(AR3=1,AR4=1,AR5=1)),1,0)} -> 0 | AU3: {=O3} -> Mexico | AX3: {=Y2} -> Grupo A | AY3: {=O3} -> Mexico | AZ3: {=P3*3+Q3} -> 9 | BA3: {=COUNTIFS($AX$1:AX3,AX3,$AZ$1:AZ3,AZ3)} -> 1 | BB3: {=IF(AZ3=BF1,ROW()*0.001,AZ3)} -> 9 | BC3: {=COUNTIFS($AX$1:AZ3,AZ3,$AZ$1:BB3,BB3)} -> 1 | BE3: {=IF(OR(BF3="-",BI3="-",BF1=0),"-","OK")} -> - | BF3: {=IF(_xlfn.XLOOKUP($E3,$AY1:$AY108,$AZ1:$AZ108,"-",0)=BF1,$E3,"-")} -> - | BG3: {=$F3} -> 2 | BH3: {=$G3} -> 0 | BI3: {=IF(_xlfn.XLOOKUP($H3,$AY1:$AY108,$AZ1:$AZ108,"-",0)=BF1,$H3,"-")} -> - | BK3: {=O3} -> Mexico | BL3: {=COUNTIFS($BE1:$BE108,"OK",$BI1:$BI108,BK3)+COUNTIFS($BE1:$BE108,"OK",$BF1:$BF108,BK3)} -> 0 | BM3: {=COUNTIFS(J1:J108,$BK3,$BE1:$BE108,"OK")} -> 0 | BN3: {=COUNTIFS(K1:K108,$BK3,$BE1:$BE108,"OK")+COUNTIFS(L1:L108,$BK3,$BE1:$BE108,"OK")} -> 0 | BO3: {=COUNTIFS(M1:M108,$BK3,$BE1:$BE108,"OK")} -> 0 | BP3: {=BQ3-BR3} -> 0 | BQ3: {=SUMIFS(BG1:BG108,$BE1:$BE108,"OK",BF1:BF108,$BK3)+SUMIFS(BH1:BH108,$BE1:$BE108,"OK",BI1:BI108,$BK3)} -> 0 | BR3: {=SUMIFS(BH1:BH108,$BE1:$BE108,"OK",BF1:BF108,$BK3)+SUMIFS(BG1:BG108,$BE1:$BE108,"OK",BI1:BI108,$BK3)} -> 0 | BS3: {=BM3*3+BN3*1+BP3/100+BQ3/10000} -> 0 | BT3: {=IF(BL3=0,0,_xlfn.XLOOKUP(BS3,BV3:BV6,BW3:BW6))} -> 0 | BV3: {=LARGE(BS3:BS6,1)} -> 1.0001 | BW3: {=BX3/$BW$1} -> 0.3 | BX3: 3 | BY3: {=IF(OR(BZ3="-",CC3="-"),"-","OK")} -> - | BZ3: {=IF(_xlfn.XLOOKUP($E3,$AY1:$AY108,$AZ1:$AZ108,"-",0)=BZ1,$E3,"-")} -> - | CA3: {=$F3} -> 2 | CB3: {=$G3} -> 0 | CC3: {=IF(_xlfn.XLOOKUP($H3,$AY1:$AY108,$AZ1:$AZ108,"-",0)=BZ1,$H3,"-")} -> - | CE3: {=BK3} -> Mexico | CF3: {=COUNTIFS($BY1:$BY108,"OK",$CC1:$CC108,CE3)+COUNTIFS($BY1:$BY108,"OK",$BZ1:$BZ108,CE3)} -> 0 | CG3: {=COUNTIFS(P1:P108,$BK3,$BY1:$BY108,"OK")} -> 0 | CH3: {=COUNTIFS(K1:K108,$BK3,$BY1:$BY108,"OK")+COUNTIFS(L1:L108,$BK3,$BY1:$BY108,"OK")} -> 0 | CI3: {=COUNTIFS(M1:M108,$CE3,$BY1:$BY108,"OK")} -> 0 | CJ3: {=CK3-CL3} -> 0 | CK3: {=SUMIFS(CA1:CA108,$BY1:$BY108,"OK",BZ1:BZ108,$BK3)+SUMIFS(CB1:CB108,$BY1:$BY108,"OK",CC1:CC108,$BK3)} -> 0 | CL3: {=SUMIFS(CB1:CB108,$BY1:$BY108,"OK",BZ1:BZ108,$BK3)+SUMIFS(CA1:CA108,$BY1:$BY108,"OK",CC1:CC108,$BK3)} -> 0 | CM3: {=CG3*3+CH3*1+CJ3/100+CK3/10000} -> 0 | CN3: {=IF(CF3=0,0,_xlfn.XLOOKUP(CM3,CP3:CP6,CQ3:CQ6))} -> 0 | CP3: {=LARGE(CM3:CM6,1)} -> 0 | CQ3: {=CR3/$BW$1} -> 0.3 | CR3: 3 | CS3: {=12*12} -> 144 | CV3: {='Mejores 3eros'!AP3} -> Bosnia | CW3: {=_xlfn.XLOOKUP(CV3,'Mejores 3eros'!$BD$2:$BD$13,'Mejores 3eros'!$BG$2:$BG$13,"-",0)} -> OUT | CX3: -
A4: GA2 | B4: 46184 | E4: Corea del Sur | F4: 1 | G4: 1 | H4: Repubilca Checa | J4: {=IF(OR(ISBLANK(F4),ISBLANK(G4)),"",IF(F4>G4,E4,IF(G4>F4,H4,"")))} | K4: {=IF(OR(ISBLANK(F4),ISBLANK(G4)),"",IF(F4=G4,E4,""))} -> Corea del Sur | L4: {=IF(OR(ISBLANK(F4),ISBLANK(G4)),"",IF(F4=G4,H4,""))} -> Repubilca Checa | M4: {=IF(OR(ISBLANK(F4),ISBLANK(G4)),"",IF(F4<G4,E4,IF(G4<F4,H4,"")))} | O4: {=H3} -> Sudafrica | P4: {=COUNTIF(J3:J8,"="&$O4)} -> 0 | Q4: {=COUNTIF(K3:L8,"="&$O4)} -> 0 | R4: {=COUNTIF(M3:M8,"="&$O4)} -> 3 | S4: {=T4-U4} -> -4 | T4: {=SUMIF(E3:E8,$O4,F3:F8)+SUMIF(H3:H8,$O4,G3:G8)} -> 0 | U4: {=SUMIF(E3:E8,$O4,G3:G8)+SUMIF(H3:H8,$O4,F3:F8)} -> 4 | V4: {=P4*3+Q4*1+BT4+CN4+S4/1000+T4/10000+AV4/1000000+ROW()/10000000} -> -0.0039996 | W4: {=O4} -> Sudafrica | Y4: {=CONCATENATE("2",RIGHT(E2,1))} -> 2A | Z4: {=VLOOKUP(AL4,V3:W6,2,FALSE)} -> Corea del Sur | AA4: {=SUM(AB4:AD4)} -> 3 | AB4: {=VLOOKUP($Z4,$O$3:$U$6,COLUMN()-26,FALSE)} -> 1 | AC4: {=VLOOKUP($Z4,$O$3:$U$6,COLUMN()-26,FALSE)} -> 1 | AD4: {=VLOOKUP($Z4,$O$3:$U$6,COLUMN()-26,FALSE)} -> 1 | AE4: {=VLOOKUP($Z4,$O$3:$U$6,COLUMN()-26,FALSE)} -> 0 | AF4: {=VLOOKUP($Z4,$O$3:$U$6,COLUMN()-26,FALSE)} -> 3 | AG4: {=VLOOKUP($Z4,$O$3:$U$6,COLUMN()-26,FALSE)} -> 3 | AH4: {=VLOOKUP($Z4,$O$3:$V$6,COLUMN()-26,FALSE)} -> 4.3003005 | AL4: {=LARGE(V3:V6,2)} -> 4.3003005 | AM4: {=(AH4-AL4)*100000000000000000000} -> 0 | AP4: {=O4} -> Sudafrica | AQ4: {=P4*3+Q4*1+BT4+CN4+S4/1000+T4/10000} -> -0.004 | AR4: {=IF(OR(AQ4=AQ5,AQ4=AQ6),1)} -> FALSE | AS4: {=AV4} -> 0 | AT4: {=IF(AND(AM7="si",OR(AR3=1,AR4=1,AR5=1)),1,0)} -> 0 | AU4: {=O4} -> Sudafrica | AX4: {=Y2} -> Grupo A | AY4: {=O4} -> Sudafrica | AZ4: {=P4*3+Q4} -> 0 | BA4: {=COUNTIFS($AX$1:AX4,AX4,$AZ$1:AZ4,AZ4)} -> 1 | BB4: {=IF(AZ4=BF1,ROW()*0.001,AZ4)} -> 0 | BC4: {=COUNTIFS($AX$1:AZ4,AZ4,$AZ$1:BB4,BB4)} -> 1 | BE4: {=IF(OR(BF4="-",BI4="-",BF1=0),"-","OK")} -> OK | BF4: {=IF(_xlfn.XLOOKUP($E4,$AY1:$AY108,$AZ1:$AZ108,"-",0)=BF1,$E4,"-")} -> Corea del Sur | BG4: {=$F4} -> 1 | BH4: {=$G4} -> 1 | BI4: {=IF(_xlfn.XLOOKUP($H4,$AY1:$AY108,$AZ1:$AZ108,"-",0)=BF1,$H4,"-")} -> Repubilca Checa | BK4: {=O4} -> Sudafrica | BL4: {=COUNTIFS($BE1:$BE108,"OK",$BI1:$BI108,BK4)+COUNTIFS($BE1:$BE108,"OK",$BF1:$BF108,BK4)} -> 0 | BM4: {=COUNTIFS(J1:J108,$BK4,$BE1:$BE108,"OK")} -> 0 | BN4: {=COUNTIFS(K1:K108,$BK4,$BE1:$BE108,"OK")+COUNTIFS(L1:L108,$BK4,$BE1:$BE108,"OK")} -> 0 | BO4: {=COUNTIFS(M1:M108,$BK4,$BE1:$BE108,"OK")} -> 0 | BP4: {=BQ4-BR4} -> 0 | BQ4: {=SUMIFS(BG1:BG108,$BE1:$BE108,"OK",BF1:BF108,$BK4)+SUMIFS(BH1:BH108,$BE1:$BE108,"OK",BI1:BI108,$BK4)} -> 0 | BR4: {=SUMIFS(BH1:BH108,$BE1:$BE108,"OK",BF1:BF108,$BK4)+SUMIFS(BG1:BG108,$BE1:$BE108,"OK",BI1:BI108,$BK4)} -> 0 | BS4: {=BM4*3+BN4*1+BP4/100+BQ4/10000} -> 0 | BT4: {=IF(BL4=0,0,_xlfn.XLOOKUP(BS4,BV3:BV6,BW3:BW6))} -> 0 | BV4: {=LARGE(BS3:BS6,2)} -> 1.0001 | BW4: {=BX4/$BW$1} -> 0.2 | BX4: 2 | BY4: {=IF(OR(BZ4="-",CC4="-"),"-","OK")} -> - | BZ4: {=IF(_xlfn.XLOOKUP($E4,$AY1:$AY108,$AZ1:$AZ108,"-",0)=BZ1,$E4,"-")} -> - | CA4: {=$F4} -> 1 | CB4: {=$G4} -> 1 | CC4: {=IF(_xlfn.XLOOKUP($H4,$AY1:$AY108,$AZ1:$AZ108,"-",0)=BZ1,$H4,"-")} -> - | CE4: {=BK4} -> Sudafrica | CF4: {=COUNTIFS($BY1:$BY108,"OK",$CC1:$CC108,CE4)+COUNTIFS($BY1:$BY108,"OK",$BZ1:$BZ108,CE4)} -> 0 | CG4: {=COUNTIFS(P1:P108,$BK4,$BY1:$BY108,"OK")} -> 0 | CH4: {=COUNTIFS(K1:K108,$BK4,$BY1:$BY108,"OK")+COUNTIFS(L1:L108,$BK4,$BY1:$BY108,"OK")} -> 0 | CI4: {=COUNTIFS(M1:M108,$CE4,$BY1:$BY108,"OK")} -> 0 | CJ4: {=CK4-CL4} -> 0 | CK4: {=SUMIFS(CA1:CA108,$BY1:$BY108,"OK",BZ1:BZ108,$BK4)+SUMIFS(CB1:CB108,$BY1:$BY108,"OK",CC1:CC108,$BK4)} -> 0 | CL4: {=SUMIFS(CB1:CB108,$BY1:$BY108,"OK",BZ1:BZ108,$BK4)+SUMIFS(CA1:CA108,$BY1:$BY108,"OK",CC1:CC108,$BK4)} -> 0 | CM4: {=CG4*3+CH4*1+CJ4/100+CK4/10000} -> 0 | CN4: {=IF(CF4=0,0,_xlfn.XLOOKUP(CM4,CP3:CP6,CQ3:CQ6))} -> 0 | CP4: {=LARGE(CM3:CM6,2)} -> 0 | CQ4: {=CR4/$BW$1} -> 0.2 | CR4: 2 | CS4: {=IF(CS2=CS3,"OK","-")} -> OK | CV4: {='Mejores 3eros'!AP4} -> Escocia | CW4: {=_xlfn.XLOOKUP(CV4,'Mejores 3eros'!$BD$2:$BD$13,'Mejores 3eros'!$BG$2:$BG$13,"-",0)} -> IN
A5: GA3 | B5: 46191 | E5: Repubilca Checa | F5: 1 | G5: 0 | H5: Sudafrica | J5: {=IF(OR(ISBLANK(F5),ISBLANK(G5)),"",IF(F5>G5,E5,IF(G5>F5,H5,"")))} -> Repubilca Checa | K5: {=IF(OR(ISBLANK(F5),ISBLANK(G5)),"",IF(F5=G5,E5,""))} | L5: {=IF(OR(ISBLANK(F5),ISBLANK(G5)),"",IF(F5=G5,H5,""))} | M5: {=IF(OR(ISBLANK(F5),ISBLANK(G5)),"",IF(F5<G5,E5,IF(G5<F5,H5,"")))} -> Sudafrica | O5: {=E4} -> Corea del Sur | P5: {=COUNTIF(J3:J8,"="&$O5)} -> 1 | Q5: {=COUNTIF(K3:L8,"="&$O5)} -> 1 | R5: {=COUNTIF(M3:M8,"="&$O5)} -> 1 | S5: {=T5-U5} -> 0 | T5: {=SUMIF(E3:E8,$O5,F3:F8)+SUMIF(H3:H8,$O5,G3:G8)} -> 3 | U5: {=SUMIF(E3:E8,$O5,G3:G8)+SUMIF(H3:H8,$O5,F3:F8)} -> 3 | V5: {=P5*3+Q5*1+BT5+CN5+S5/1000+T5/10000+AV5/1000000+ROW()/10000000} -> 4.3003005 | W5: {=O5} -> Corea del Sur | Y5: {=CONCATENATE("3",RIGHT(E2,1))} -> 3A | Z5: {=VLOOKUP(AL5,V3:W6,2,FALSE)} -> Repubilca Checa | AA5: {=SUM(AB5:AD5)} -> 3 | AB5: {=VLOOKUP($Z5,$O$3:$U$6,COLUMN()-26,FALSE)} -> 1 | AC5: {=VLOOKUP($Z5,$O$3:$U$6,COLUMN()-26,FALSE)} -> 1 | AD5: {=VLOOKUP($Z5,$O$3:$U$6,COLUMN()-26,FALSE)} -> 1 | AE5: {=VLOOKUP($Z5,$O$3:$U$6,COLUMN()-26,FALSE)} -> 0 | AF5: {=VLOOKUP($Z5,$O$3:$U$6,COLUMN()-26,FALSE)} -> 2 | AG5: {=VLOOKUP($Z5,$O$3:$U$6,COLUMN()-26,FALSE)} -> 2 | AH5: {=VLOOKUP($Z5,$O$3:$V$6,COLUMN()-26,FALSE)} -> 4.3002006 | AI5: {=(COUNTIFS($CV$2:$CV$13,Z5,$CX$2:$CX$13,"IN")+COUNTIFS($CV$2:$CV$13,Z5,$CW$2:$CW$13,"IN"))*IF(SUM(AA3:AA6)=12,1,0)} -> 1 | AL5: {=LARGE(V3:V6,3)} -> 4.3002006 | AM5: {=(AH5-AL5)*100000000000000000000} -> 0 | AP5: {=O5} -> Corea del Sur | AQ5: {=P5*3+Q5*1+BT5+CN5+S5/1000+T5/10000} -> 4.3003 | AR5: {=IF(OR(AQ5=AQ6),1)} -> FALSE | AS5: {=AV5} -> 0 | AT5: {=IF(AND(AM7="si",OR(AR3=1,AR4=1,AR5=1)),1,0)} -> 0 | AU5: {=O5} -> Corea del Sur | AX5: {=Y2} -> Grupo A | AY5: {=O5} -> Corea del Sur | AZ5: {=P5*3+Q5} -> 4 | BA5: {=COUNTIFS($AX$1:AX5,AX5,$AZ$1:AZ5,AZ5)} -> 1 | BB5: {=IF(AZ5=BF1,ROW()*0.001,AZ5)} -> 0.005 | BC5: {=COUNTIFS($AX$1:AZ5,AZ5,$AZ$1:BB5,BB5)} -> 1 | BE5: {=IF(OR(BF5="-",BI5="-",BF1=0),"-","OK")} -> - | BF5: {=IF(_xlfn.XLOOKUP($E5,$AY1:$AY108,$AZ1:$AZ108,"-",0)=BF1,$E5,"-")} -> Repubilca Checa | BG5: {=$F5} -> 1 | BH5: {=$G5} -> 0 | BI5: {=IF(_xlfn.XLOOKUP($H5,$AY1:$AY108,$AZ1:$AZ108,"-",0)=BF1,$H5,"-")} -> - | BK5: {=O5} -> Corea del Sur | BL5: {=COUNTIFS($BE1:$BE108,"OK",$BI1:$BI108,BK5)+COUNTIFS($BE1:$BE108,"OK",$BF1:$BF108,BK5)} -> 1 | BM5: {=COUNTIFS(J1:J108,$BK5,$BE1:$BE108,"OK")} -> 0 | BN5: {=COUNTIFS(K1:K108,$BK5,$BE1:$BE108,"OK")+COUNTIFS(L1:L108,$BK5,$BE1:$BE108,"OK")} -> 1 | BO5: {=COUNTIFS(M1:M108,$BK5,$BE1:$BE108,"OK")} -> 0 | BP5: {=BQ5-BR5} -> 0 | BQ5: {=SUMIFS(BG1:BG108,$BE1:$BE108,"OK",BF1:BF108,$BK5)+SUMIFS(BH1:BH108,$BE1:$BE108,"OK",BI1:BI108,$BK5)} -> 1 | BR5: {=SUMIFS(BH1:BH108,$BE1:$BE108,"OK",BF1:BF108,$BK5)+SUMIFS(BG1:BG108,$BE1:$BE108,"OK",BI1:BI108,$BK5)} -> 1 | BS5: {=BM5*3+BN5*1+BP5/100+BQ5/10000} -> 1.0001 | BT5: {=IF(BL5=0,0,_xlfn.XLOOKUP(BS5,BV3:BV6,BW3:BW6))} -> 0.3 | BV5: {=LARGE(BS3:BS6,3)} -> 0 | BW5: {=BX5/$BW$1} -> 0.1 | BX5: 1 | BY5: {=IF(OR(BZ5="-",CC5="-"),"-","OK")} -> - | BZ5: {=IF(_xlfn.XLOOKUP($E5,$AY1:$AY108,$AZ1:$AZ108,"-",0)=BZ1,$E5,"-")} -> - | CA5: {=$F5} -> 1 | CB5: {=$G5} -> 0 | CC5: {=IF(_xlfn.XLOOKUP($H5,$AY1:$AY108,$AZ1:$AZ108,"-",0)=BZ1,$H5,"-")} -> - | CE5: {=BK5} -> Corea del Sur | CF5: {=COUNTIFS($BY1:$BY108,"OK",$CC1:$CC108,CE5)+COUNTIFS($BY1:$BY108,"OK",$BZ1:$BZ108,CE5)} -> 0 | CG5: {=COUNTIFS(P1:P108,$BK5,$BY1:$BY108,"OK")} -> 0 | CH5: {=COUNTIFS(K1:K108,$BK5,$BY1:$BY108,"OK")+COUNTIFS(L1:L108,$BK5,$BY1:$BY108,"OK")} -> 0 | CI5: {=COUNTIFS(M1:M108,$CE5,$BY1:$BY108,"OK")} -> 0 | CJ5: {=CK5-CL5} -> 0 | CK5: {=SUMIFS(CA1:CA108,$BY1:$BY108,"OK",BZ1:BZ108,$BK5)+SUMIFS(CB1:CB108,$BY1:$BY108,"OK",CC1:CC108,$BK5)} -> 0 | CL5: {=SUMIFS(CB1:CB108,$BY1:$BY108,"OK",BZ1:BZ108,$BK5)+SUMIFS(CA1:CA108,$BY1:$BY108,"OK",CC1:CC108,$BK5)} -> 0 | CM5: {=CG5*3+CH5*1+CJ5/100+CK5/10000} -> 0 | CN5: {=IF(CF5=0,0,_xlfn.XLOOKUP(CM5,CP3:CP6,CQ3:CQ6))} -> 0 | CP5: {=LARGE(CM3:CM6,3)} -> 0 | CQ5: {=CR5/$BW$1} -> 0.1 | CR5: 1 | CV5: {='Mejores 3eros'!AP5} -> Turquia | CW5: {=_xlfn.XLOOKUP(CV5,'Mejores 3eros'!$BD$2:$BD$13,'Mejores 3eros'!$BG$2:$BG$13,"-",0)} -> IN | CX5: -
A6: GA4 | B6: 46191 | E6: Mexico | F6: 2 | G6: 1 | H6: Corea del Sur | J6: {=IF(OR(ISBLANK(F6),ISBLANK(G6)),"",IF(F6>G6,E6,IF(G6>F6,H6,"")))} -> Mexico | K6: {=IF(OR(ISBLANK(F6),ISBLANK(G6)),"",IF(F6=G6,E6,""))} | L6: {=IF(OR(ISBLANK(F6),ISBLANK(G6)),"",IF(F6=G6,H6,""))} | M6: {=IF(OR(ISBLANK(F6),ISBLANK(G6)),"",IF(F6<G6,E6,IF(G6<F6,H6,"")))} -> Corea del Sur | O6: {=H4} -> Repubilca Checa | P6: {=COUNTIF(J3:J8,"="&$O6)} -> 1 | Q6: {=COUNTIF(K3:L8,"="&$O6)} -> 1 | R6: {=COUNTIF(M3:M8,"="&$O6)} -> 1 | S6: {=T6-U6} -> 0 | T6: {=SUMIF(E3:E8,$O6,F3:F8)+SUMIF(H3:H8,$O6,G3:G8)} -> 2 | U6: {=SUMIF(E3:E8,$O6,G3:G8)+SUMIF(H3:H8,$O6,F3:F8)} -> 2 | V6: {=P6*3+Q6*1+BT6+CN6+S6/1000+T6/10000+AV6/1000000+ROW()/10000000} -> 4.3002006 | W6: {=O6} -> Repubilca Checa | Y6: {=CONCATENATE("4",RIGHT(E2,1))} -> 4A | Z6: {=VLOOKUP(AL6,V3:W6,2,FALSE)} -> Sudafrica | AA6: {=SUM(AB6:AD6)} -> 3 | AB6: {=VLOOKUP($Z6,$O$3:$U$6,COLUMN()-26,FALSE)} -> 0 | AC6: {=VLOOKUP($Z6,$O$3:$U$6,COLUMN()-26,FALSE)} -> 0 | AD6: {=VLOOKUP($Z6,$O$3:$U$6,COLUMN()-26,FALSE)} -> 3 | AE6: {=VLOOKUP($Z6,$O$3:$U$6,COLUMN()-26,FALSE)} -> -4 | AF6: {=VLOOKUP($Z6,$O$3:$U$6,COLUMN()-26,FALSE)} -> 0 | AG6: {=VLOOKUP($Z6,$O$3:$U$6,COLUMN()-26,FALSE)} -> 4 | AH6: {=VLOOKUP($Z6,$O$3:$V$6,COLUMN()-26,FALSE)} -> -0.0039996 | AL6: {=LARGE(V3:V6,4)} -> -0.0039996 | AM6: {=(AH6-AL6)*100000000000000000000} -> 0 | AP6: {=O6} -> Repubilca Checa | AQ6: {=P6*3+Q6*1+BT6+CN6+S6/1000+T6/10000} -> 4.3002 | AS6: {=AV6} -> 0 | AT6: {=IF(AND(AM7="si",OR(AR3=1,AR4=1,AR5=1)),1,0)} -> 0 | AU6: {=O6} -> Repubilca Checa | AX6: {=Y2} -> Grupo A | AY6: {=O6} -> Repubilca Checa | AZ6: {=P6*3+Q6} -> 4 | BA6: {=COUNTIFS($AX$1:AX6,AX6,$AZ$1:AZ6,AZ6)} -> 2 | BB6: {=IF(AZ6=BF1,ROW()*0.001,AZ6)} -> 0.006 | BC6: {=COUNTIFS($AX$1:AZ6,AZ6,$AZ$1:BB6,BB6)} -> 1 | BE6: {=IF(OR(BF6="-",BI6="-",BF1=0),"-","OK")} -> - | BF6: {=IF(_xlfn.XLOOKUP($E6,$AY1:$AY108,$AZ1:$AZ108,"-",0)=BF1,$E6,"-")} -> - | BG6: {=$F6} -> 2 | BH6: {=$G6} -> 1 | BI6: {=IF(_xlfn.XLOOKUP($H6,$AY1:$AY108,$AZ1:$AZ108,"-",0)=BF1,$H6,"-")} -> Corea del Sur | BK6: {=O6} -> Repubilca Checa | BL6: {=COUNTIFS($BE1:$BE108,"OK",$BI1:$BI108,BK6)+COUNTIFS($BE1:$BE108,"OK",$BF1:$BF108,BK6)} -> 1 | BM6: {=COUNTIFS(J1:J108,$BK6,$BE1:$BE108,"OK")} -> 0 | BN6: {=COUNTIFS(K1:K108,$BK6,$BE1:$BE108,"OK")+COUNTIFS(L1:L108,$BK6,$BE1:$BE108,"OK")} -> 1 | BO6: {=COUNTIFS(M1:M108,$BK6,$BE1:$BE108,"OK")} -> 0 | BP6: {=BQ6-BR6} -> 0 | BQ6: {=SUMIFS(BG1:BG108,$BE1:$BE108,"OK",BF1:BF108,$BK6)+SUMIFS(BH1:BH108,$BE1:$BE108,"OK",BI1:BI108,$BK6)} -> 1 | BR6: {=SUMIFS(BH1:BH108,$BE1:$BE108,"OK",BF1:BF108,$BK6)+SUMIFS(BG1:BG108,$BE1:$BE108,"OK",BI1:BI108,$BK6)} -> 1 | BS6: {=BM6*3+BN6*1+BP6/100+BQ6/10000} -> 1.0001 | BT6: {=IF(BL6=0,0,_xlfn.XLOOKUP(BS6,BV3:BV6,BW3:BW6))} -> 0.3 | BV6: {=LARGE(BS3:BS6,4)} -> 0 | BW6: {=BX6/$BW$1} -> 0 | BX6: 0 | BY6: {=IF(OR(BZ6="-",CC6="-"),"-","OK")} -> - | BZ6: {=IF(_xlfn.XLOOKUP($E6,$AY1:$AY108,$AZ1:$AZ108,"-",0)=BZ1,$E6,"-")} -> - | CA6: {=$F6} -> 2 | CB6: {=$G6} -> 1 | CC6: {=IF(_xlfn.XLOOKUP($H6,$AY1:$AY108,$AZ1:$AZ108,"-",0)=BZ1,$H6,"-")} -> - | CE6: {=BK6} -> Repubilca Checa | CF6: {=COUNTIFS($BY1:$BY108,"OK",$CC1:$CC108,CE6)+COUNTIFS($BY1:$BY108,"OK",$BZ1:$BZ108,CE6)} -> 0 | CG6: {=COUNTIFS(P1:P108,$BK6,$BY1:$BY108,"OK")} -> 0 | CH6: {=COUNTIFS(K1:K108,$BK6,$BY1:$BY108,"OK")+COUNTIFS(L1:L108,$BK6,$BY1:$BY108,"OK")} -> 0 | CI6: {=COUNTIFS(M1:M108,$CE6,$BY1:$BY108,"OK")} -> 0 | CJ6: {=CK6-CL6} -> 0 | CK6: {=SUMIFS(CA1:CA108,$BY1:$BY108,"OK",BZ1:BZ108,$BK6)+SUMIFS(CB1:CB108,$BY1:$BY108,"OK",CC1:CC108,$BK6)} -> 0 | CL6: {=SUMIFS(CB1:CB108,$BY1:$BY108,"OK",BZ1:BZ108,$BK6)+SUMIFS(CA1:CA108,$BY1:$BY108,"OK",CC1:CC108,$BK6)} -> 0 | CM6: {=CG6*3+CH6*1+CJ6/100+CK6/10000} -> 0 | CN6: {=IF(CF6=0,0,_xlfn.XLOOKUP(CM6,CP3:CP6,CQ3:CQ6))} -> 0 | CP6: {=LARGE(CM3:CM6,4)} -> 0 | CQ6: {=CR6/$BW$1} -> 0 | CR6: 0 | CV6: {='Mejores 3eros'!AP6} -> Costa de Marfil | CW6: {=_xlfn.XLOOKUP(CV6,'Mejores 3eros'!$BD$2:$BD$13,'Mejores 3eros'!$BG$2:$BG$13,"-",0)} -> IN | CX6: -
A7: GA5 | B7: 46197 | E7: Repubilca Checa | F7: 0 | G7: 1 | H7: Mexico | J7: {=IF(OR(ISBLANK(F7),ISBLANK(G7)),"",IF(F7>G7,E7,IF(G7>F7,H7,"")))} -> Mexico | K7: {=IF(OR(ISBLANK(F7),ISBLANK(G7)),"",IF(F7=G7,E7,""))} | L7: {=IF(OR(ISBLANK(F7),ISBLANK(G7)),"",IF(F7=G7,H7,""))} | M7: {=IF(OR(ISBLANK(F7),ISBLANK(G7)),"",IF(F7<G7,E7,IF(G7<F7,H7,"")))} -> Repubilca Checa | AL7: Completo? | AM7: {=IF(SUM(AA3:AA6)=12,"si","no")} -> si | BE7: {=IF(OR(BF7="-",BI7="-",BF1=0),"-","OK")} -> - | BF7: {=IF(_xlfn.XLOOKUP($E7,$AY1:$AY108,$AZ1:$AZ108,"-",0)=BF1,$E7,"-")} -> Repubilca Checa | BG7: {=$F7} -> 0 | BH7: {=$G7} -> 1 | BI7: {=IF(_xlfn.XLOOKUP($H7,$AY1:$AY108,$AZ1:$AZ108,"-",0)=BF1,$H7,"-")} -> - | BY7: {=IF(OR(BZ7="-",CC7="-"),"-","OK")} -> - | BZ7: {=IF(_xlfn.XLOOKUP($E7,$AY1:$AY108,$AZ1:$AZ108,"-",0)=BZ1,$E7,"-")} -> - | CA7: {=$F7} -> 0 | CB7: {=$G7} -> 1 | CC7: {=IF(_xlfn.XLOOKUP($H7,$AY1:$AY108,$AZ1:$AZ108,"-",0)=BZ1,$H7,"-")} -> - | CV7: {='Mejores 3eros'!AP7} -> Suecia | CW7: {=_xlfn.XLOOKUP(CV7,'Mejores 3eros'!$BD$2:$BD$13,'Mejores 3eros'!$BG$2:$BG$13,"-",0)} -> IN | CX7: -
A8: GA6 | B8: 46197 | E8: Sudafrica | F8: 0 | G8: 1 | H8: Corea del Sur | J8: {=IF(OR(ISBLANK(F8),ISBLANK(G8)),"",IF(F8>G8,E8,IF(G8>F8,H8,"")))} -> Corea del Sur | K8: {=IF(OR(ISBLANK(F8),ISBLANK(G8)),"",IF(F8=G8,E8,""))} | L8: {=IF(OR(ISBLANK(F8),ISBLANK(G8)),"",IF(F8=G8,H8,""))} | M8: {=IF(OR(ISBLANK(F8),ISBLANK(G8)),"",IF(F8<G8,E8,IF(G8<F8,H8,"")))} -> Sudafrica | Y8: Hay equipos empatados: completar tabla para definir sorteo (valores del 1 al 4, el 4 pasa de ronda) | AR8: {=IF(AND(AM7="si",OR(AR3=1,AR4=1,AR5=1)),1,0)} -> 0 | BE8: {=IF(OR(BF8="-",BI8="-",BF1=0),"-","OK")} -> - | BF8: {=IF(_xlfn.XLOOKUP($E8,$AY1:$AY108,$AZ1:$AZ108,"-",0)=BF1,$E8,"-")} -> - | BG8: {=$F8} -> 0 | BH8: {=$G8} -> 1 | BI8: {=IF(_xlfn.XLOOKUP($H8,$AY1:$AY108,$AZ1:$AZ108,"-",0)=BF1,$H8,"-")} -> Corea del Sur | BY8: {=IF(OR(BZ8="-",CC8="-"),"-","OK")} -> - | BZ8: {=IF(_xlfn.XLOOKUP($E8,$AY1:$AY108,$AZ1:$AZ108,"-",0)=BZ1,$E8,"-")} -> - | CA8: {=$F8} -> 0 | CB8: {=$G8} -> 1 | CC8: {=IF(_xlfn.XLOOKUP($H8,$AY1:$AY108,$AZ1:$AZ108,"-",0)=BZ1,$H8,"-")} -> - | CV8: {='Mejores 3eros'!AP8} -> Iran | CW8: {=_xlfn.XLOOKUP(CV8,'Mejores 3eros'!$BD$2:$BD$13,'Mejores 3eros'!$BG$2:$BG$13,"-",0)} -> OUT | CX8: -
CV9: {='Mejores 3eros'!AP9} -> Arabia Saudita | CW9: {=_xlfn.XLOOKUP(CV9,'Mejores 3eros'!$BD$2:$BD$13,'Mejores 3eros'!$BG$2:$BG$13,"-",0)} -> OUT | CX9: -
BF10: {=IF(BA12>1,AZ12,IF(BA13>1,AZ13,IF(BA14>1,AZ14,IF(BA15>1,AZ15,"-"))))} -> 1 | BW10: 10 | BZ10: {=IF(BC12>1,BB12,IF(BC13>1,BB13,IF(BC14>1,BB14,IF(BC15>1,BB15,"-"))))} -> 7 | CQ10: 10 | CV10: {='Mejores 3eros'!AP10} -> Senegal | CW10: {=_xlfn.XLOOKUP(CV10,'Mejores 3eros'!$BD$2:$BD$13,'Mejores 3eros'!$BG$2:$BG$13,"-",0)} -> IN
A11: Partido | B11: Fecha | C11: Sede | E11: Grupo B | J11: G | K11: E | L11: E | M11: P | O11: {=E11} -> Grupo B | P11: G | Q11: E | R11: P | S11: Dif | T11: G+ | U11: G- | V11: Ptos | Y11: Grupo B | AA11: J | AB11: G | AC11: E | AD11: P | AE11: Dif | AF11: G+ | AG11: G- | AH11: Ptos | AL11: Ptos | AM11: check | AY11: Empate 1 | AZ11: Ptos | BA11: Empate? | BL11: J | BM11: G | BN11: E | BO11: P | BP11: Dif | BQ11: G+ | BR11: G- | BS11: Ptos | BT11: Extra | BV11: Orden | BW11: Extra | CF11: J | CG11: G | CH11: E | CI11: P | CJ11: Dif | CK11: G+ | CL11: G- | CM11: Ptos | CN11: Extra | CP11: Orden | CQ11: Extra | CV11: {='Mejores 3eros'!AP11} -> Argelia | CW11: {=_xlfn.XLOOKUP(CV11,'Mejores 3eros'!$BD$2:$BD$13,'Mejores 3eros'!$BG$2:$BG$13,"-",0)} -> IN | CX11: -
A12: GB1 | B12: 46185 | E12: Canada | F12: 1 | G12: 0 | H12: Bosnia | J12: {=IF(OR(ISBLANK(F12),ISBLANK(G12)),"",IF(F12>G12,E12,IF(G12>F12,H12,"")))} -> Canada | K12: {=IF(OR(ISBLANK(F12),ISBLANK(G12)),"",IF(F12=G12,E12,""))} | L12: {=IF(OR(ISBLANK(F12),ISBLANK(G12)),"",IF(F12=G12,H12,""))} | M12: {=IF(OR(ISBLANK(F12),ISBLANK(G12)),"",IF(F12<G12,E12,IF(G12<F12,H12,"")))} -> Bosnia | O12: {=E12} -> Canada | P12: {=COUNTIF(J12:J17,"="&$O12)} -> 2 | Q12: {=COUNTIF(K12:L17,"="&$O12)} -> 1 | R12: {=COUNTIF(M12:M17,"="&$O12)} -> 0 | S12: {=T12-U12} -> 3 | T12: {=SUMIF(E12:E17,$O12,F12:F17)+SUMIF(H12:H17,$O12,G12:G17)} -> 4 | U12: {=SUMIF(E12:E17,$O12,G12:G17)+SUMIF(H12:H17,$O12,F12:F17)} -> 1 | V12: {=P12*3+Q12*1+BT12+CN12+S12/1000+T12/10000+AV12/1000000+ROW()/10000000} -> 7.3034012 | W12: {=O12} -> Canada | Y12: {=CONCATENATE("1",RIGHT(E11,1))} -> 1B | Z12: {=VLOOKUP(AL12,V12:W15,2,FALSE)} -> Suiza | AA12: {=SUM(AB12:AD12)} -> 3 | AB12: {=VLOOKUP($Z12,$O$12:$U$15,COLUMN()-26,FALSE)} -> 2 | AC12: {=VLOOKUP($Z12,$O$12:$U$15,COLUMN()-26,FALSE)} -> 1 | AD12: {=VLOOKUP($Z12,$O$12:$U$15,COLUMN()-26,FALSE)} -> 0 | AE12: {=VLOOKUP($Z12,$O$12:$U$15,COLUMN()-26,FALSE)} -> 3 | AF12: {=VLOOKUP($Z12,$O$12:$U$15,COLUMN()-26,FALSE)} -> 4 | AG12: {=VLOOKUP($Z12,$O$12:$U$15,COLUMN()-26,FALSE)} -> 1 | AH12: {=VLOOKUP($Z12,$O$12:$V$15,COLUMN()-26,FALSE)} -> 7.3034015 | AL12: {=LARGE(V12:V15,1)} -> 7.3034015 | AM12: {=(AH12-AL12)*100000000000000000000} -> 0 | AP12: {=O12} -> Canada | AQ12: {=P12*3+Q12*1+BT12+CN12+S12/1000+T12/10000} -> 7.3034 | AR12: {=IF(OR(AQ12=AQ13,AQ12=AQ14,AQ12=AQ15),1)} -> 1 | AS12: {=AV12} -> 0 | AT12: {=IF(AND(AM16="si",OR(AR12=1,AR13=1,AR14=1)),1,0)} -> 1 | AU12: {=O12} -> Canada | AX12: {=Y11} -> Grupo B | AY12: {=O12} -> Canada | AZ12: {=P12*3+Q12} -> 7 | BA12: {=COUNTIFS($AX$1:AX12,AX12,$AZ$1:AZ12,AZ12)} -> 1 | BB12: {=IF(AZ12=BF10,ROW()*0.001,AZ12)} -> 7 | BC12: {=COUNTIFS($AX$1:AZ12,AZ12,$AZ$1:BB12,BB12)} -> 1 | BE12: {=IF(OR(BF12="-",BI12="-",BF10=0),"-","OK")} -> - | BF12: {=IF(_xlfn.XLOOKUP($E12,$AY1:$AY108,$AZ1:$AZ108,"-",0)=BF10,$E12,"-")} -> - | BG12: {=$F12} -> 1 | BH12: {=$G12} -> 0 | BI12: {=IF(_xlfn.XLOOKUP($H12,$AY1:$AY108,$AZ1:$AZ108,"-",0)=BF10,$H12,"-")} -> Bosnia | BK12: {=O12} -> Canada | BL12: {=COUNTIFS($BE1:$BE108,"OK",$BI1:$BI108,BK12)+COUNTIFS($BE1:$BE108,"OK",$BF1:$BF108,BK12)} -> 0 | BM12: {=COUNTIFS(J1:J108,$BK12,$BE1:$BE108,"OK")} -> 0 | BN12: {=COUNTIFS(K1:K108,$BK12,$BE1:$BE108,"OK")+COUNTIFS(L1:L108,$BK12,$BE1:$BE108,"OK")} -> 0 | BO12: {=COUNTIFS(M1:M108,$BK12,$BE1:$BE108,"OK")} -> 0 | BP12: {=BQ12-BR12} -> 0 | BQ12: {=SUMIFS(BG1:BG108,$BE1:$BE108,"OK",BF1:BF108,$BK12)+SUMIFS(BH1:BH108,$BE1:$BE108,"OK",BI1:BI108,$BK12)} -> 0 | BR12: {=SUMIFS(BH1:BH108,$BE1:$BE108,"OK",BF1:BF108,$BK12)+SUMIFS(BG1:BG108,$BE1:$BE108,"OK",BI1:BI108,$BK12)} -> 0 | BS12: {=BM12*3+BN12*1+BP12/100+BQ12/10000} -> 0 | BT12: {=IF(BL12=0,0,_xlfn.XLOOKUP(BS12,BV12:BV15,BW12:BW15))} -> 0 | BV12: {=LARGE(BS12:BS15,1)} -> 1.0001 | BW12: {=BX12/$BW$1} -> 0.3 | BX12: 3 | BY12: {=IF(OR(BZ12="-",CC12="-"),"-","OK")} -> - | BZ12: {=IF(_xlfn.XLOOKUP($E12,$AY1:$AY108,$AZ1:$AZ108,"-",0)=BZ10,$E12,"-")} -> Canada | CA12: {=$F12} -> 1 | CB12: {=$G12} -> 0 | CC12: {=IF(_xlfn.XLOOKUP($H12,$AY1:$AY108,$AZ1:$AZ108,"-",0)=BZ10,$H12,"-")} -> - | CE12: {=BK12} -> Canada | CF12: {=COUNTIFS($BY1:$BY108,"OK",$CC1:$CC108,CE12)+COUNTIFS($BY1:$BY108,"OK",$BZ1:$BZ108,CE12)} -> 1 | CG12: {=COUNTIFS(P1:P108,$BK12,$BY1:$BY108,"OK")} -> 0 | CH12: {=COUNTIFS(K1:K108,$BK12,$BY1:$BY108,"OK")+COUNTIFS(L1:L108,$BK12,$BY1:$BY108,"OK")} -> 1 | CI12: {=COUNTIFS(M1:M108,$CE12,$BY1:$BY108,"OK")} -> 0 | CJ12: {=CK12-CL12} -> 0 | CK12: {=SUMIFS(CA1:CA108,$BY1:$BY108,"OK",BZ1:BZ108,$BK12)+SUMIFS(CB1:CB108,$BY1:$BY108,"OK",CC1:CC108,$BK12)} -> 1 | CL12: {=SUMIFS(CB1:CB108,$BY1:$BY108,"OK",BZ1:BZ108,$BK12)+SUMIFS(CA1:CA108,$BY1:$BY108,"OK",CC1:CC108,$BK12)} -> 1 | CM12: {=CG12*3+CH12*1+CJ12/100+CK12/10000} -> 1.0001 | CN12: {=IF(CF12=0,0,_xlfn.XLOOKUP(CM12,CP12:CP15,CQ12:CQ15))} -> 0.3 | CP12: {=LARGE(CM12:CM15,1)} -> 1.0001 | CQ12: {=CR12/$BW$1} -> 0.3 | CR12: 3 | CV12: {='Mejores 3eros'!AP12} -> Congo | CW12: {=_xlfn.XLOOKUP(CV12,'Mejores 3eros'!$BD$2:$BD$13,'Mejores 3eros'!$BG$2:$BG$13,"-",0)} -> OUT | CX12: -
A13: GB2 | B13: 46186 | E13: Qatar | F13: 0 | G13: 2 | H13: Suiza | J13: {=IF(OR(ISBLANK(F13),ISBLANK(G13)),"",IF(F13>G13,E13,IF(G13>F13,H13,"")))} -> Suiza | K13: {=IF(OR(ISBLANK(F13),ISBLANK(G13)),"",IF(F13=G13,E13,""))} | L13: {=IF(OR(ISBLANK(F13),ISBLANK(G13)),"",IF(F13=G13,H13,""))} | M13: {=IF(OR(ISBLANK(F13),ISBLANK(G13)),"",IF(F13<G13,E13,IF(G13<F13,H13,"")))} -> Qatar | O13: {=H12} -> Bosnia | P13: {=COUNTIF(J12:J17,"="&$O13)} -> 0 | Q13: {=COUNTIF(K12:L17,"="&$O13)} -> 1 | R13: {=COUNTIF(M12:M17,"="&$O13)} -> 2 | S13: {=T13-U13} -> -2 | T13: {=SUMIF(E12:E17,$O13,F12:F17)+SUMIF(H12:H17,$O13,G12:G17)} -> 1 | U13: {=SUMIF(E12:E17,$O13,G12:G17)+SUMIF(H12:H17,$O13,F12:F17)} -> 3 | V13: {=P13*3+Q13*1+BT13+CN13+S13/1000+T13/10000+AV13/1000000+ROW()/10000000} -> 1.2981013 | W13: {=O13} -> Bosnia | Y13: {=CONCATENATE("2",RIGHT(E11,1))} -> 2B | Z13: {=VLOOKUP(AL13,V12:W15,2,FALSE)} -> Canada | AA13: {=SUM(AB13:AD13)} -> 3 | AB13: {=VLOOKUP($Z13,$O$12:$U$15,COLUMN()-26,FALSE)} -> 2 | AC13: {=VLOOKUP($Z13,$O$12:$U$15,COLUMN()-26,FALSE)} -> 1 | AD13: {=VLOOKUP($Z13,$O$12:$U$15,COLUMN()-26,FALSE)} -> 0 | AE13: {=VLOOKUP($Z13,$O$12:$U$15,COLUMN()-26,FALSE)} -> 3 | AF13: {=VLOOKUP($Z13,$O$12:$U$15,COLUMN()-26,FALSE)} -> 4 | AG13: {=VLOOKUP($Z13,$O$12:$U$15,COLUMN()-26,FALSE)} -> 1 | AH13: {=VLOOKUP($Z13,$O$12:$V$15,COLUMN()-26,FALSE)} -> 7.3034012 | AL13: {=LARGE(V12:V15,2)} -> 7.3034012 | AM13: {=(AH13-AL13)*100000000000000000000} -> 0 | AP13: {=O13} -> Bosnia | AQ13: {=P13*3+Q13*1+BT13+CN13+S13/1000+T13/10000} -> 1.2981 | AR13: {=IF(OR(AQ13=AQ14,AQ13=AQ15),1)} -> FALSE | AS13: {=AV13} -> 0 | AT13: {=IF(AND(AM16="si",OR(AR12=1,AR13=1,AR14=1)),1,0)} -> 1 | AU13: {=O13} -> Bosnia | AX13: {=Y11} -> Grupo B | AY13: {=O13} -> Bosnia | AZ13: {=P13*3+Q13} -> 1 | BA13: {=COUNTIFS($AX$1:AX13,AX13,$AZ$1:AZ13,AZ13)} -> 1 | BB13: {=IF(AZ13=BF10,ROW()*0.001,AZ13)} -> 0.013 | BC13: {=COUNTIFS($AX$1:AZ13,AZ13,$AZ$1:BB13,BB13)} -> 1 | BE13: {=IF(OR(BF13="-",BI13="-",BF10=0),"-","OK")} -> - | BF13: {=IF(_xlfn.XLOOKUP($E13,$AY1:$AY108,$AZ1:$AZ108,"-",0)=BF10,$E13,"-")} -> Qatar | BG13: {=$F13} -> 0 | BH13: {=$G13} -> 2 | BI13: {=IF(_xlfn.XLOOKUP($H13,$AY1:$AY108,$AZ1:$AZ108,"-",0)=BF10,$H13,"-")} -> - | BK13: {=O13} -> Bosnia | BL13: {=COUNTIFS($BE1:$BE108,"OK",$BI1:$BI108,BK13)+COUNTIFS($BE1:$BE108,"OK",$BF1:$BF108,BK13)} -> 1 | BM13: {=COUNTIFS(J1:J108,$BK13,$BE1:$BE108,"OK")} -> 0 | BN13: {=COUNTIFS(K1:K108,$BK13,$BE1:$BE108,"OK")+COUNTIFS(L1:L108,$BK13,$BE1:$BE108,"OK")} -> 1 | BO13: {=COUNTIFS(M1:M108,$BK13,$BE1:$BE108,"OK")} -> 0 | BP13: {=BQ13-BR13} -> 0 | BQ13: {=SUMIFS(BG1:BG108,$BE1:$BE108,"OK",BF1:BF108,$BK13)+SUMIFS(BH1:BH108,$BE1:$BE108,"OK",BI1:BI108,$BK13)} -> 1 | BR13: {=SUMIFS(BH1:BH108,$BE1:$BE108,"OK",BF1:BF108,$BK13)+SUMIFS(BG1:BG108,$BE1:$BE108,"OK",BI1:BI108,$BK13)} -> 1 | BS13: {=BM13*3+BN13*1+BP13/100+BQ13/10000} -> 1.0001 | BT13: {=IF(BL13=0,0,_xlfn.XLOOKUP(BS13,BV12:BV15,BW12:BW15))} -> 0.3 | BV13: {=LARGE(BS12:BS15,2)} -> 1.0001 | BW13: {=BX13/$BW$1} -> 0.2 | BX13: 2 | BY13: {=IF(OR(BZ13="-",CC13="-"),"-","OK")} -> - | BZ13: {=IF(_xlfn.XLOOKUP($E13,$AY1:$AY108,$AZ1:$AZ108,"-",0)=BZ10,$E13,"-")} -> - | CA13: {=$F13} -> 0 | CB13: {=$G13} -> 2 | CC13: {=IF(_xlfn.XLOOKUP($H13,$AY1:$AY108,$AZ1:$AZ108,"-",0)=BZ10,$H13,"-")} -> Suiza | CE13: {=BK13} -> Bosnia | CF13: {=COUNTIFS($BY1:$BY108,"OK",$CC1:$CC108,CE13)+COUNTIFS($BY1:$BY108,"OK",$BZ1:$BZ108,CE13)} -> 0 | CG13: {=COUNTIFS(P1:P108,$BK13,$BY1:$BY108,"OK")} -> 0 | CH13: {=COUNTIFS(K1:K108,$BK13,$BY1:$BY108,"OK")+COUNTIFS(L1:L108,$BK13,$BY1:$BY108,"OK")} -> 0 | CI13: {=COUNTIFS(M1:M108,$CE13,$BY1:$BY108,"OK")} -> 0 | CJ13: {=CK13-CL13} -> 0 | CK13: {=SUMIFS(CA1:CA108,$BY1:$BY108,"OK",BZ1:BZ108,$BK13)+SUMIFS(CB1:CB108,$BY1:$BY108,"OK",CC1:CC108,$BK13)} -> 0 | CL13: {=SUMIFS(CB1:CB108,$BY1:$BY108,"OK",BZ1:BZ108,$BK13)+SUMIFS(CA1:CA108,$BY1:$BY108,"OK",CC1:CC108,$BK13)} -> 0 | CM13: {=CG13*3+CH13*1+CJ13/100+CK13/10000} -> 0 | CN13: {=IF(CF13=0,0,_xlfn.XLOOKUP(CM13,CP12:CP15,CQ12:CQ15))} -> 0 | CP13: {=LARGE(CM12:CM15,2)} -> 1.0001 | CQ13: {=CR13/$BW$1} -> 0.2 | CR13: 2 | CV13: {='Mejores 3eros'!AP13} -> Ghana | CW13: {=_xlfn.XLOOKUP(CV13,'Mejores 3eros'!$BD$2:$BD$13,'Mejores 3eros'!$BG$2:$BG$13,"-",0)} -> IN | CX13: -
A14: GB3 | B14: 46191 | E14: Suiza | F14: 1 | G14: 0 | H14: Bosnia | J14: {=IF(OR(ISBLANK(F14),ISBLANK(G14)),"",IF(F14>G14,E14,IF(G14>F14,H14,"")))} -> Suiza | K14: {=IF(OR(ISBLANK(F14),ISBLANK(G14)),"",IF(F14=G14,E14,""))} | L14: {=IF(OR(ISBLANK(F14),ISBLANK(G14)),"",IF(F14=G14,H14,""))} | M14: {=IF(OR(ISBLANK(F14),ISBLANK(G14)),"",IF(F14<G14,E14,IF(G14<F14,H14,"")))} -> Bosnia | O14: {=E13} -> Qatar | P14: {=COUNTIF(J12:J17,"="&$O14)} -> 0 | Q14: {=COUNTIF(K12:L17,"="&$O14)} -> 1 | R14: {=COUNTIF(M12:M17,"="&$O14)} -> 2 | S14: {=T14-U14} -> -4 | T14: {=SUMIF(E12:E17,$O14,F12:F17)+SUMIF(H12:H17,$O14,G12:G17)} -> 1 | U14: {=SUMIF(E12:E17,$O14,G12:G17)+SUMIF(H12:H17,$O14,F12:F17)} -> 5 | V14: {=P14*3+Q14*1+BT14+CN14+S14/1000+T14/10000+AV14/1000000+ROW()/10000000} -> 1.2961014 | W14: {=O14} -> Qatar | Y14: {=CONCATENATE("3",RIGHT(E11,1))} -> 3B | Z14: {=VLOOKUP(AL14,V12:W15,2,FALSE)} -> Bosnia | AA14: {=SUM(AB14:AD14)} -> 3 | AB14: {=VLOOKUP($Z14,$O$12:$U$15,COLUMN()-26,FALSE)} -> 0 | AC14: {=VLOOKUP($Z14,$O$12:$U$15,COLUMN()-26,FALSE)} -> 1 | AD14: {=VLOOKUP($Z14,$O$12:$U$15,COLUMN()-26,FALSE)} -> 2 | AE14: {=VLOOKUP($Z14,$O$12:$U$15,COLUMN()-26,FALSE)} -> -2 | AF14: {=VLOOKUP($Z14,$O$12:$U$15,COLUMN()-26,FALSE)} -> 1 | AG14: {=VLOOKUP($Z14,$O$12:$U$15,COLUMN()-26,FALSE)} -> 3 | AH14: {=VLOOKUP($Z14,$O$12:$V$15,COLUMN()-26,FALSE)} -> 1.2981013 | AI14: {=(COUNTIFS($CV$2:$CV$13,Z14,$CX$2:$CX$13,"IN")+COUNTIFS($CV$2:$CV$13,Z14,$CW$2:$CW$13,"IN"))*IF(SUM(AA12:AA15)=12,1,0)} -> 0 | AL14: {=LARGE(V12:V15,3)} -> 1.2981013 | AM14: {=(AH14-AL14)*100000000000000000000} -> 0 | AP14: {=O14} -> Qatar | AQ14: {=P14*3+Q14*1+BT14+CN14+S14/1000+T14/10000} -> 1.2961 | AR14: {=IF(OR(AQ14=AQ15),1)} -> FALSE | AS14: {=AV14} -> 0 | AT14: {=IF(AND(AM16="si",OR(AR12=1,AR13=1,AR14=1)),1,0)} -> 1 | AU14: {=O14} -> Qatar | AX14: {=Y11} -> Grupo B | AY14: {=O14} -> Qatar | AZ14: {=P14*3+Q14} -> 1 | BA14: {=COUNTIFS($AX$1:AX14,AX14,$AZ$1:AZ14,AZ14)} -> 2 | BB14: {=IF(AZ14=BF10,ROW()*0.001,AZ14)} -> 0.014 | BC14: {=COUNTIFS($AX$1:AZ14,AZ14,$AZ$1:BB14,BB14)} -> 1 | BE14: {=IF(OR(BF14="-",BI14="-",BF10=0),"-","OK")} -> - | BF14: {=IF(_xlfn.XLOOKUP($E14,$AY1:$AY108,$AZ1:$AZ108,"-",0)=BF10,$E14,"-")} -> - | BG14: {=$F14} -> 1 | BH14: {=$G14} -> 0 | BI14: {=IF(_xlfn.XLOOKUP($H14,$AY1:$AY108,$AZ1:$AZ108,"-",0)=BF10,$H14,"-")} -> Bosnia | BK14: {=O14} -> Qatar | BL14: {=COUNTIFS($BE1:$BE108,"OK",$BI1:$BI108,BK14)+COUNTIFS($BE1:$BE108,"OK",$BF1:$BF108,BK14)} -> 1 | BM14: {=COUNTIFS(J1:J108,$BK14,$BE1:$BE108,"OK")} -> 0 | BN14: {=COUNTIFS(K1:K108,$BK14,$BE1:$BE108,"OK")+COUNTIFS(L1:L108,$BK14,$BE1:$BE108,"OK")} -> 1 | BO14: {=COUNTIFS(M1:M108,$BK14,$BE1:$BE108,"OK")} -> 0 | BP14: {=BQ14-BR14} -> 0 | BQ14: {=SUMIFS(BG1:BG108,$BE1:$BE108,"OK",BF1:BF108,$BK14)+SUMIFS(BH1:BH108,$BE1:$BE108,"OK",BI1:BI108,$BK14)} -> 1 | BR14: {=SUMIFS(BH1:BH108,$BE1:$BE108,"OK",BF1:BF108,$BK14)+SUMIFS(BG1:BG108,$BE1:$BE108,"OK",BI1:BI108,$BK14)} -> 1 | BS14: {=BM14*3+BN14*1+BP14/100+BQ14/10000} -> 1.0001 | BT14: {=IF(BL14=0,0,_xlfn.XLOOKUP(BS14,BV12:BV15,BW12:BW15))} -> 0.3 | BV14: {=LARGE(BS12:BS15,3)} -> 0 | BW14: {=BX14/$BW$1} -> 0.1 | BX14: 1 | BY14: {=IF(OR(BZ14="-",CC14="-"),"-","OK")} -> - | BZ14: {=IF(_xlfn.XLOOKUP($E14,$AY1:$AY108,$AZ1:$AZ108,"-",0)=BZ10,$E14,"-")} -> Suiza | CA14: {=$F14} -> 1 | CB14: {=$G14} -> 0 | CC14: {=IF(_xlfn.XLOOKUP($H14,$AY1:$AY108,$AZ1:$AZ108,"-",0)=BZ10,$H14,"-")} -> - | CE14: {=BK14} -> Qatar | CF14: {=COUNTIFS($BY1:$BY108,"OK",$CC1:$CC108,CE14)+COUNTIFS($BY1:$BY108,"OK",$BZ1:$BZ108,CE14)} -> 0 | CG14: {=COUNTIFS(P1:P108,$BK14,$BY1:$BY108,"OK")} -> 0 | CH14: {=COUNTIFS(K1:K108,$BK14,$BY1:$BY108,"OK")+COUNTIFS(L1:L108,$BK14,$BY1:$BY108,"OK")} -> 0 | CI14: {=COUNTIFS(M1:M108,$CE14,$BY1:$BY108,"OK")} -> 0 | CJ14: {=CK14-CL14} -> 0 | CK14: {=SUMIFS(CA1:CA108,$BY1:$BY108,"OK",BZ1:BZ108,$BK14)+SUMIFS(CB1:CB108,$BY1:$BY108,"OK",CC1:CC108,$BK14)} -> 0 | CL14: {=SUMIFS(CB1:CB108,$BY1:$BY108,"OK",BZ1:BZ108,$BK14)+SUMIFS(CA1:CA108,$BY1:$BY108,"OK",CC1:CC108,$BK14)} -> 0 | CM14: {=CG14*3+CH14*1+CJ14/100+CK14/10000} -> 0 | CN14: {=IF(CF14=0,0,_xlfn.XLOOKUP(CM14,CP12:CP15,CQ12:CQ15))} -> 0 | CP14: {=LARGE(CM12:CM15,3)} -> 0 | CQ14: {=CR14/$BW$1} -> 0.1 | CR14: 1 | CV14: -
A15: GB4 | B15: 46191 | E15: Canada | F15: 2 | G15: 0 | H15: Qatar | J15: {=IF(OR(ISBLANK(F15),ISBLANK(G15)),"",IF(F15>G15,E15,IF(G15>F15,H15,"")))} -> Canada | K15: {=IF(OR(ISBLANK(F15),ISBLANK(G15)),"",IF(F15=G15,E15,""))} | L15: {=IF(OR(ISBLANK(F15),ISBLANK(G15)),"",IF(F15=G15,H15,""))} | M15: {=IF(OR(ISBLANK(F15),ISBLANK(G15)),"",IF(F15<G15,E15,IF(G15<F15,H15,"")))} -> Qatar | O15: {=H13} -> Suiza | P15: {=COUNTIF(J12:J17,"="&$O15)} -> 2 | Q15: {=COUNTIF(K12:L17,"="&$O15)} -> 1 | R15: {=COUNTIF(M12:M17,"="&$O15)} -> 0 | S15: {=T15-U15} -> 3 | T15: {=SUMIF(E12:E17,$O15,F12:F17)+SUMIF(H12:H17,$O15,G12:G17)} -> 4 | U15: {=SUMIF(E12:E17,$O15,G12:G17)+SUMIF(H12:H17,$O15,F12:F17)} -> 1 | V15: {=P15*3+Q15*1+BT15+CN15+S15/1000+T15/10000+AV15/1000000+ROW()/10000000} -> 7.3034015 | W15: {=O15} -> Suiza | Y15: {=CONCATENATE("4",RIGHT(E11,1))} -> 4B | Z15: {=VLOOKUP(AL15,V12:W15,2,FALSE)} -> Qatar | AA15: {=SUM(AB15:AD15)} -> 3 | AB15: {=VLOOKUP($Z15,$O$12:$U$15,COLUMN()-26,FALSE)} -> 0 | AC15: {=VLOOKUP($Z15,$O$12:$U$15,COLUMN()-26,FALSE)} -> 1 | AD15: {=VLOOKUP($Z15,$O$12:$U$15,COLUMN()-26,FALSE)} -> 2 | AE15: {=VLOOKUP($Z15,$O$12:$U$15,COLUMN()-26,FALSE)} -> -4 | AF15: {=VLOOKUP($Z15,$O$12:$U$15,COLUMN()-26,FALSE)} -> 1 | AG15: {=VLOOKUP($Z15,$O$12:$U$15,COLUMN()-26,FALSE)} -> 5 | AH15: {=VLOOKUP($Z15,$O$12:$V$15,COLUMN()-26,FALSE)} -> 1.2961014 | AL15: {=LARGE(V12:V15,4)} -> 1.2961014 | AM15: {=(AH15-AL15)*100000000000000000000} -> 0 | AP15: {=O15} -> Suiza | AQ15: {=P15*3+Q15*1+BT15+CN15+S15/1000+T15/10000} -> 7.3034 | AS15: {=AV15} -> 0 | AT15: {=IF(AND(AM16="si",OR(AR12=1,AR13=1,AR14=1)),1,0)} -> 1 | AU15: {=O15} -> Suiza | AX15: {=Y11} -> Grupo B | AY15: {=O15} -> Suiza | AZ15: {=P15*3+Q15} -> 7 | BA15: {=COUNTIFS($AX$1:AX15,AX15,$AZ$1:AZ15,AZ15)} -> 2 | BB15: {=IF(AZ15=BF10,ROW()*0.001,AZ15)} -> 7 | BC15: {=COUNTIFS($AX$1:AZ15,AZ15,$AZ$1:BB15,BB15)} -> 2 | BE15: {=IF(OR(BF15="-",BI15="-",BF10=0),"-","OK")} -> - | BF15: {=IF(_xlfn.XLOOKUP($E15,$AY1:$AY108,$AZ1:$AZ108,"-",0)=BF10,$E15,"-")} -> - | BG15: {=$F15} -> 2 | BH15: {=$G15} -> 0 | BI15: {=IF(_xlfn.XLOOKUP($H15,$AY1:$AY108,$AZ1:$AZ108,"-",0)=BF10,$H15,"-")} -> Qatar | BK15: {=O15} -> Suiza | BL15: {=COUNTIFS($BE1:$BE108,"OK",$BI1:$BI108,BK15)+COUNTIFS($BE1:$BE108,"OK",$BF1:$BF108,BK15)} -> 0 | BM15: {=COUNTIFS(J1:J108,$BK15,$BE1:$BE108,"OK")} -> 0 | BN15: {=COUNTIFS(K1:K108,$BK15,$BE1:$BE108,"OK")+COUNTIFS(L1:L108,$BK15,$BE1:$BE108,"OK")} -> 0 | BO15: {=COUNTIFS(M1:M108,$BK15,$BE1:$BE108,"OK")} -> 0 | BP15: {=BQ15-BR15} -> 0 | BQ15: {=SUMIFS(BG1:BG108,$BE1:$BE108,"OK",BF1:BF108,$BK15)+SUMIFS(BH1:BH108,$BE1:$BE108,"OK",BI1:BI108,$BK15)} -> 0 | BR15: {=SUMIFS(BH1:BH108,$BE1:$BE108,"OK",BF1:BF108,$BK15)+SUMIFS(BG1:BG108,$BE1:$BE108,"OK",BI1:BI108,$BK15)} -> 0 | BS15: {=BM15*3+BN15*1+BP15/100+BQ15/10000} -> 0 | BT15: {=IF(BL15=0,0,_xlfn.XLOOKUP(BS15,BV12:BV15,BW12:BW15))} -> 0 | BV15: {=LARGE(BS12:BS15,4)} -> 0 | BW15: {=BX15/$BW$1} -> 0 | BX15: 0 | BY15: {=IF(OR(BZ15="-",CC15="-"),"-","OK")} -> - | BZ15: {=IF(_xlfn.XLOOKUP($E15,$AY1:$AY108,$AZ1:$AZ108,"-",0)=BZ10,$E15,"-")} -> Canada | CA15: {=$F15} -> 2 | CB15: {=$G15} -> 0 | CC15: {=IF(_xlfn.XLOOKUP($H15,$AY1:$AY108,$AZ1:$AZ108,"-",0)=BZ10,$H15,"-")} -> - | CE15: {=BK15} -> Suiza | CF15: {=COUNTIFS($BY1:$BY108,"OK",$CC1:$CC108,CE15)+COUNTIFS($BY1:$BY108,"OK",$BZ1:$BZ108,CE15)} -> 1 | CG15: {=COUNTIFS(P1:P108,$BK15,$BY1:$BY108,"OK")} -> 0 | CH15: {=COUNTIFS(K1:K108,$BK15,$BY1:$BY108,"OK")+COUNTIFS(L1:L108,$BK15,$BY1:$BY108,"OK")} -> 1 | CI15: {=COUNTIFS(M1:M108,$CE15,$BY1:$BY108,"OK")} -> 0 | CJ15: {=CK15-CL15} -> 0 | CK15: {=SUMIFS(CA1:CA108,$BY1:$BY108,"OK",BZ1:BZ108,$BK15)+SUMIFS(CB1:CB108,$BY1:$BY108,"OK",CC1:CC108,$BK15)} -> 1 | CL15: {=SUMIFS(CB1:CB108,$BY1:$BY108,"OK",BZ1:BZ108,$BK15)+SUMIFS(CA1:CA108,$BY1:$BY108,"OK",CC1:CC108,$BK15)} -> 1 | CM15: {=CG15*3+CH15*1+CJ15/100+CK15/10000} -> 1.0001 | CN15: {=IF(CF15=0,0,_xlfn.XLOOKUP(CM15,CP12:CP15,CQ12:CQ15))} -> 0.3 | CP15: {=LARGE(CM12:CM15,4)} -> 0 | CQ15: {=CR15/$BW$1} -> 0 | CR15: 0 | CW15: {=ROUNDDOWN(RAND()*4,0)} -> 1
A16: GB5 | B16: 46197 | E16: Suiza | F16: 1 | G16: 1 | H16: Canada | J16: {=IF(OR(ISBLANK(F16),ISBLANK(G16)),"",IF(F16>G16,E16,IF(G16>F16,H16,"")))} | K16: {=IF(OR(ISBLANK(F16),ISBLANK(G16)),"",IF(F16=G16,E16,""))} -> Suiza | L16: {=IF(OR(ISBLANK(F16),ISBLANK(G16)),"",IF(F16=G16,H16,""))} -> Canada | M16: {=IF(OR(ISBLANK(F16),ISBLANK(G16)),"",IF(F16<G16,E16,IF(G16<F16,H16,"")))} | AL16: Completo? | AM16: {=IF(SUM(AA12:AA15)=12,"si","no")} -> si | BE16: {=IF(OR(BF16="-",BI16="-",BF10=0),"-","OK")} -> - | BF16: {=IF(_xlfn.XLOOKUP($E16,$AY1:$AY108,$AZ1:$AZ108,"-",0)=BF10,$E16,"-")} -> - | BG16: {=$F16} -> 1 | BH16: {=$G16} -> 1 | BI16: {=IF(_xlfn.XLOOKUP($H16,$AY1:$AY108,$AZ1:$AZ108,"-",0)=BF10,$H16,"-")} -> - | BY16: {=IF(OR(BZ16="-",CC16="-"),"-","OK")} -> OK | BZ16: {=IF(_xlfn.XLOOKUP($E16,$AY1:$AY108,$AZ1:$AZ108,"-",0)=BZ10,$E16,"-")} -> Suiza | CA16: {=$F16} -> 1 | CB16: {=$G16} -> 1 | CC16: {=IF(_xlfn.XLOOKUP($H16,$AY1:$AY108,$AZ1:$AZ108,"-",0)=BZ10,$H16,"-")} -> Canada
A17: GB6 | B17: 46197 | E17: Bosnia | F17: 1 | G17: 1 | H17: Qatar | J17: {=IF(OR(ISBLANK(F17),ISBLANK(G17)),"",IF(F17>G17,E17,IF(G17>F17,H17,"")))} | K17: {=IF(OR(ISBLANK(F17),ISBLANK(G17)),"",IF(F17=G17,E17,""))} -> Bosnia | L17: {=IF(OR(ISBLANK(F17),ISBLANK(G17)),"",IF(F17=G17,H17,""))} -> Qatar | M17: {=IF(OR(ISBLANK(F17),ISBLANK(G17)),"",IF(F17<G17,E17,IF(G17<F17,H17,"")))} | Y17: Hay equipos empatados: completar tabla para definir sorteo (valores del 1 al 4, el 4 pasa de ronda) | AR17: {=IF(AND(AM16="si",OR(AR12=1,AR13=1,AR14=1)),1,0)} -> 1 | BE17: {=IF(OR(BF17="-",BI17="-",BF10=0),"-","OK")} -> OK | BF17: {=IF(_xlfn.XLOOKUP($E17,$AY1:$AY108,$AZ1:$AZ108,"-",0)=BF10,$E17,"-")} -> Bosnia | BG17: {=$F17} -> 1 | BH17: {=$G17} -> 1 | BI17: {=IF(_xlfn.XLOOKUP($H17,$AY1:$AY108,$AZ1:$AZ108,"-",0)=BF10,$H17,"-")} -> Qatar | BY17: {=IF(OR(BZ17="-",CC17="-"),"-","OK")} -> - | BZ17: {=IF(_xlfn.XLOOKUP($E17,$AY1:$AY108,$AZ1:$AZ108,"-",0)=BZ10,$E17,"-")} -> - | CA17: {=$F17} -> 1 | CB17: {=$G17} -> 1 | CC17: {=IF(_xlfn.XLOOKUP($H17,$AY1:$AY108,$AZ1:$AZ108,"-",0)=BZ10,$H17,"-")} -> -
BF19: {=IF(BA21>1,AZ21,IF(BA22>1,AZ22,IF(BA23>1,AZ23,IF(BA24>1,AZ24,"-"))))} -> - | BW19: 10 | BZ19: {=IF(BC21>1,BB21,IF(BC22>1,BB22,IF(BC23>1,BB23,IF(BC24>1,BB24,"-"))))} -> 9 | CQ19: 10
A20: Partido | B20: Fecha | C20: Sede | E20: Grupo C | J20: G | K20: E | L20: E | M20: P | O20: {=E20} -> Grupo C | P20: G | Q20: E | R20: P | S20: Dif | T20: G+ | U20: G- | V20: Ptos | Y20: Grupo C | AA20: J | AB20: G | AC20: E | AD20: P | AE20: Dif | AF20: G+ | AG20: G- | AH20: Ptos | AL20: Ptos | AM20: check | AY20: Empate 1 | AZ20: Ptos | BA20: Empate? | BL20: J | BM20: G | BN20: E | BO20: P | BP20: Dif | BQ20: G+ | BR20: G- | BS20: Ptos | BT20: Extra | BV20: Orden | BW20: Extra | CF20: J | CG20: G | CH20: E | CI20: P | CJ20: Dif | CK20: G+ | CL20: G- | CM20: Ptos | CN20: Extra | CP20: Orden | CQ20: Extra
A21: GC1 | B21: 46186 | E21: Brasil | F21: 2 | G21: 1 | H21: Marruecos | J21: {=IF(OR(ISBLANK(F21),ISBLANK(G21)),"",IF(F21>G21,E21,IF(G21>F21,H21,"")))} -> Brasil | K21: {=IF(OR(ISBLANK(F21),ISBLANK(G21)),"",IF(F21=G21,E21,""))} | L21: {=IF(OR(ISBLANK(F21),ISBLANK(G21)),"",IF(F21=G21,H21,""))} | M21: {=IF(OR(ISBLANK(F21),ISBLANK(G21)),"",IF(F21<G21,E21,IF(G21<F21,H21,"")))} -> Marruecos | O21: {=E21} -> Brasil | P21: {=COUNTIF(J21:J26,"="&$O21)} -> 3 | Q21: {=COUNTIF(K21:L26,"="&$O21)} -> 0 | R21: {=COUNTIF(M21:M26,"="&$O21)} -> 0 | S21: {=T21-U21} -> 5 | T21: {=SUMIF(E21:E26,$O21,F21:F26)+SUMIF(H21:H26,$O21,G21:G26)} -> 7 | U21: {=SUMIF(E21:E26,$O21,G21:G26)+SUMIF(H21:H26,$O21,F21:F26)} -> 2 | V21: {=P21*3+Q21*1+BT21+CN21+S21/1000+T21/10000+AV21/1000000+ROW()/10000000} -> 9.0057021 | W21: {=O21} -> Brasil | Y21: {=CONCATENATE("1",RIGHT(E20,1))} -> 1C | Z21: {=VLOOKUP(AL21,V21:W24,2,FALSE)} -> Brasil | AA21: {=SUM(AB21:AD21)} -> 3 | AB21: {=VLOOKUP($Z21,$O$21:$U$24,COLUMN()-26,FALSE)} -> 3 | AC21: {=VLOOKUP($Z21,$O$21:$U$24,COLUMN()-26,FALSE)} -> 0 | AD21: {=VLOOKUP($Z21,$O$21:$U$24,COLUMN()-26,FALSE)} -> 0 | AE21: {=VLOOKUP($Z21,$O$21:$U$24,COLUMN()-26,FALSE)} -> 5 | AF21: {=VLOOKUP($Z21,$O$21:$U$24,COLUMN()-26,FALSE)} -> 7 | AG21: {=VLOOKUP($Z21,$O$21:$U$24,COLUMN()-26,FALSE)} -> 2 | AH21: {=VLOOKUP($Z21,$O$21:$V$24,COLUMN()-26,FALSE)} -> 9.0057021 | AL21: {=LARGE(V21:V24,1)} -> 9.0057021 | AM21: {=(AH21-AL21)*100000000000000000000} -> 0 | AP21: {=O21} -> Brasil | AQ21: {=P21*3+Q21*1+BT21+CN21+S21/1000+T21/10000} -> 9.0057 | AR21: {=IF(OR(AQ21=AQ22,AQ21=AQ23,AQ21=AQ24),1)} -> FALSE | AS21: {=AV21} -> 0 | AT21: {=IF(AND(AM25="si",OR(AR21=1,AR22=1,AR23=1)),1,0)} -> 0 | AU21: {=O21} -> Brasil | AX21: {=Y20} -> Grupo C | AY21: {=O21} -> Brasil | AZ21: {=P21*3+Q21} -> 9 | BA21: {=COUNTIFS($AX$1:AX21,AX21,$AZ$1:AZ21,AZ21)} -> 1 | BB21: {=IF(AZ21=BF19,ROW()*0.001,AZ21)} -> 9 | BC21: {=COUNTIFS($AX$1:AZ21,AZ21,$AZ$1:BB21,BB21)} -> 2 | BE21: {=IF(OR(BF21="-",BI21="-",BF19=0),"-","OK")} -> - | BF21: {=IF(_xlfn.XLOOKUP($E21,$AY1:$AY108,$AZ1:$AZ108,"-",0)=BF19,$E21,"-")} -> - | BG21: {=$F21} -> 2 | BH21: {=$G21} -> 1 | BI21: {=IF(_xlfn.XLOOKUP($H21,$AY1:$AY108,$AZ1:$AZ108,"-",0)=BF19,$H21,"-")} -> - | BK21: {=O21} -> Brasil | BL21: {=COUNTIFS($BE1:$BE108,"OK",$BI1:$BI108,BK21)+COUNTIFS($BE1:$BE108,"OK",$BF1:$BF108,BK21)} -> 0 | BM21: {=COUNTIFS(J1:J108,$BK21,$BE1:$BE108,"OK")} -> 0 | BN21: {=COUNTIFS(K1:K108,$BK21,$BE1:$BE108,"OK")+COUNTIFS(L1:L108,$BK21,$BE1:$BE108,"OK")} -> 0 | BO21: {=COUNTIFS(M1:M108,$BK21,$BE1:$BE108,"OK")} -> 0 | BP21: {=BQ21-BR21} -> 0 | BQ21: {=SUMIFS(BG1:BG108,$BE1:$BE108,"OK",BF1:BF108,$BK21)+SUMIFS(BH1:BH108,$BE1:$BE108,"OK",BI1:BI108,$BK21)} -> 0 | BR21: {=SUMIFS(BH1:BH108,$BE1:$BE108,"OK",BF1:BF108,$BK21)+SUMIFS(BG1:BG108,$BE1:$BE108,"OK",BI1:BI108,$BK21)} -> 0 | BS21: {=BM21*3+BN21*1+BP21/100+BQ21/10000} -> 0 | BT21: {=IF(BL21=0,0,_xlfn.XLOOKUP(BS21,BV21:BV24,BW21:BW24))} -> 0 | BV21: {=LARGE(BS21:BS24,1)} -> 0 | BW21: {=BX21/$BW$1} -> 0.3 | BX21: 3 | BY21: {=IF(OR(BZ21="-",CC21="-"),"-","OK")} -> - | BZ21: {=IF(_xlfn.XLOOKUP($E21,$AY1:$AY108,$AZ1:$AZ108,"-",0)=BZ19,$E21,"-")} -> Brasil | CA21: {=$F21} -> 2 | CB21: {=$G21} -> 1 | CC21: {=IF(_xlfn.XLOOKUP($H21,$AY1:$AY108,$AZ1:$AZ108,"-",0)=BZ19,$H21,"-")} -> - | CE21: {=BK21} -> Brasil | CF21: {=COUNTIFS($BY1:$BY108,"OK",$CC1:$CC108,CE21)+COUNTIFS($BY1:$BY108,"OK",$BZ1:$BZ108,CE21)} -> 0 | CG21: {=COUNTIFS(P1:P108,$BK21,$BY1:$BY108,"OK")} -> 0 | CH21: {=COUNTIFS(K1:K108,$BK21,$BY1:$BY108,"OK")+COUNTIFS(L1:L108,$BK21,$BY1:$BY108,"OK")} -> 0 | CI21: {=COUNTIFS(M1:M108,$CE21,$BY1:$BY108,"OK")} -> 0 | CJ21: {=CK21-CL21} -> 0 | CK21: {=SUMIFS(CA1:CA108,$BY1:$BY108,"OK",BZ1:BZ108,$BK21)+SUMIFS(CB1:CB108,$BY1:$BY108,"OK",CC1:CC108,$BK21)} -> 0 | CL21: {=SUMIFS(CB1:CB108,$BY1:$BY108,"OK",BZ1:BZ108,$BK21)+SUMIFS(CA1:CA108,$BY1:$BY108,"OK",CC1:CC108,$BK21)} -> 0 | CM21: {=CG21*3+CH21*1+CJ21/100+CK21/10000} -> 0 | CN21: {=IF(CF21=0,0,_xlfn.XLOOKUP(CM21,CP21:CP24,CQ21:CQ24))} -> 0 | CP21: {=LARGE(CM21:CM24,1)} -> 0 | CQ21: {=CR21/$BW$1} -> 0.3 | CR21: 3
A22: GC2 | B22: 46186 | E22: Haiti | F22: 0 | G22: 3 | H22: Escocia | J22: {=IF(OR(ISBLANK(F22),ISBLANK(G22)),"",IF(F22>G22,E22,IF(G22>F22,H22,"")))} -> Escocia | K22: {=IF(OR(ISBLANK(F22),ISBLANK(G22)),"",IF(F22=G22,E22,""))} | L22: {=IF(OR(ISBLANK(F22),ISBLANK(G22)),"",IF(F22=G22,H22,""))} | M22: {=IF(OR(ISBLANK(F22),ISBLANK(G22)),"",IF(F22<G22,E22,IF(G22<F22,H22,"")))} -> Haiti | O22: {=H21} -> Marruecos | P22: {=COUNTIF(J21:J26,"="&$O22)} -> 2 | Q22: {=COUNTIF(K21:L26,"="&$O22)} -> 0 | R22: {=COUNTIF(M21:M26,"="&$O22)} -> 1 | S22: {=T22-U22} -> 3 | T22: {=SUMIF(E21:E26,$O22,F21:F26)+SUMIF(H21:H26,$O22,G21:G26)} -> 6 | U22: {=SUMIF(E21:E26,$O22,G21:G26)+SUMIF(H21:H26,$O22,F21:F26)} -> 3 | V22: {=P22*3+Q22*1+BT22+CN22+S22/1000+T22/10000+AV22/1000000+ROW()/10000000} -> 6.0036022 | W22: {=O22} -> Marruecos | Y22: {=CONCATENATE("2",RIGHT(E20,1))} -> 2C | Z22: {=VLOOKUP(AL22,V21:W24,2,FALSE)} -> Marruecos | AA22: {=SUM(AB22:AD22)} -> 3 | AB22: {=VLOOKUP($Z22,$O$21:$U$24,COLUMN()-26,FALSE)} -> 2 | AC22: {=VLOOKUP($Z22,$O$21:$U$24,COLUMN()-26,FALSE)} -> 0 | AD22: {=VLOOKUP($Z22,$O$21:$U$24,COLUMN()-26,FALSE)} -> 1 | AE22: {=VLOOKUP($Z22,$O$21:$U$24,COLUMN()-26,FALSE)} -> 3 | AF22: {=VLOOKUP($Z22,$O$21:$U$24,COLUMN()-26,FALSE)} -> 6 | AG22: {=VLOOKUP($Z22,$O$21:$U$24,COLUMN()-26,FALSE)} -> 3 | AH22: {=VLOOKUP($Z22,$O$21:$V$24,COLUMN()-26,FALSE)} -> 6.0036022 | AL22: {=LARGE(V21:V24,2)} -> 6.0036022 | AM22: {=(AH22-AL22)*100000000000000000000} -> 0 | AP22: {=O22} -> Marruecos | AQ22: {=P22*3+Q22*1+BT22+CN22+S22/1000+T22/10000} -> 6.0036 | AR22: {=IF(OR(AQ22=AQ23,AQ22=AQ24),1)} -> FALSE | AS22: {=AV22} -> 0 | AT22: {=IF(AND(AM25="si",OR(AR21=1,AR22=1,AR23=1)),1,0)} -> 0 | AU22: {=O22} -> Marruecos | AX22: {=Y20} -> Grupo C | AY22: {=O22} -> Marruecos | AZ22: {=P22*3+Q22} -> 6 | BA22: {=COUNTIFS($AX$1:AX22,AX22,$AZ$1:AZ22,AZ22)} -> 1 | BB22: {=IF(AZ22=BF19,ROW()*0.001,AZ22)} -> 6 | BC22: {=COUNTIFS($AX$1:AZ22,AZ22,$AZ$1:BB22,BB22)} -> 1 | BE22: {=IF(OR(BF22="-",BI22="-",BF19=0),"-","OK")} -> - | BF22: {=IF(_xlfn.XLOOKUP($E22,$AY1:$AY108,$AZ1:$AZ108,"-",0)=BF19,$E22,"-")} -> - | BG22: {=$F22} -> 0 | BH22: {=$G22} -> 3 | BI22: {=IF(_xlfn.XLOOKUP($H22,$AY1:$AY108,$AZ1:$AZ108,"-",0)=BF19,$H22,"-")} -> - | BK22: {=O22} -> Marruecos | BL22: {=COUNTIFS($BE1:$BE108,"OK",$BI1:$BI108,BK22)+COUNTIFS($BE1:$BE108,"OK",$BF1:$BF108,BK22)} -> 0 | BM22: {=COUNTIFS(J1:J108,$BK22,$BE1:$BE108,"OK")} -> 0 | BN22: {=COUNTIFS(K1:K108,$BK22,$BE1:$BE108,"OK")+COUNTIFS(L1:L108,$BK22,$BE1:$BE108,"OK")} -> 0 | BO22: {=COUNTIFS(M1:M108,$BK22,$BE1:$BE108,"OK")} -> 0 | BP22: {=BQ22-BR22} -> 0 | BQ22: {=SUMIFS(BG1:BG108,$BE1:$BE108,"OK",BF1:BF108,$BK22)+SUMIFS(BH1:BH108,$BE1:$BE108,"OK",BI1:BI108,$BK22)} -> 0 | BR22: {=SUMIFS(BH1:BH108,$BE1:$BE108,"OK",BF1:BF108,$BK22)+SUMIFS(BG1:BG108,$BE1:$BE108,"OK",BI1:BI108,$BK22)} -> 0 | BS22: {=BM22*3+BN22*1+BP22/100+BQ22/10000} -> 0 | BT22: {=IF(BL22=0,0,_xlfn.XLOOKUP(BS22,BV21:BV24,BW21:BW24))} -> 0 | BV22: {=LARGE(BS21:BS24,2)} -> 0 | BW22: {=BX22/$BW$1} -> 0.2 | BX22: 2 | BY22: {=IF(OR(BZ22="-",CC22="-"),"-","OK")} -> - | BZ22: {=IF(_xlfn.XLOOKUP($E22,$AY1:$AY108,$AZ1:$AZ108,"-",0)=BZ19,$E22,"-")} -> - | CA22: {=$F22} -> 0 | CB22: {=$G22} -> 3 | CC22: {=IF(_xlfn.XLOOKUP($H22,$AY1:$AY108,$AZ1:$AZ108,"-",0)=BZ19,$H22,"-")} -> - | CE22: {=BK22} -> Marruecos | CF22: {=COUNTIFS($BY1:$BY108,"OK",$CC1:$CC108,CE22)+COUNTIFS($BY1:$BY108,"OK",$BZ1:$BZ108,CE22)} -> 0 | CG22: {=COUNTIFS(P1:P108,$BK22,$BY1:$BY108,"OK")} -> 0 | CH22: {=COUNTIFS(K1:K108,$BK22,$BY1:$BY108,"OK")+COUNTIFS(L1:L108,$BK22,$BY1:$BY108,"OK")} -> 0 | CI22: {=COUNTIFS(M1:M108,$CE22,$BY1:$BY108,"OK")} -> 0 | CJ22: {=CK22-CL22} -> 0 | CK22: {=SUMIFS(CA1:CA108,$BY1:$BY108,"OK",BZ1:BZ108,$BK22)+SUMIFS(CB1:CB108,$BY1:$BY108,"OK",CC1:CC108,$BK22)} -> 0 | CL22: {=SUMIFS(CB1:CB108,$BY1:$BY108,"OK",BZ1:BZ108,$BK22)+SUMIFS(CA1:CA108,$BY1:$BY108,"OK",CC1:CC108,$BK22)} -> 0 | CM22: {=CG22*3+CH22*1+CJ22/100+CK22/10000} -> 0 | CN22: {=IF(CF22=0,0,_xlfn.XLOOKUP(CM22,CP21:CP24,CQ21:CQ24))} -> 0 | CP22: {=LARGE(CM21:CM24,2)} -> 0 | CQ22: {=CR22/$BW$1} -> 0.2 | CR22: 2
A23: GC3 | B23: 46192 | E23: Brasil | F23: 3 | G23: 0 | H23: Haiti | J23: {=IF(OR(ISBLANK(F23),ISBLANK(G23)),"",IF(F23>G23,E23,IF(G23>F23,H23,"")))} -> Brasil | K23: {=IF(OR(ISBLANK(F23),ISBLANK(G23)),"",IF(F23=G23,E23,""))} | L23: {=IF(OR(ISBLANK(F23),ISBLANK(G23)),"",IF(F23=G23,H23,""))} | M23: {=IF(OR(ISBLANK(F23),ISBLANK(G23)),"",IF(F23<G23,E23,IF(G23<F23,H23,"")))} -> Haiti | O23: {=E22} -> Haiti | P23: {=COUNTIF(J21:J26,"="&$O23)} -> 0 | Q23: {=COUNTIF(K21:L26,"="&$O23)} -> 0 | R23: {=COUNTIF(M21:M26,"="&$O23)} -> 3 | S23: {=T23-U23} -> -9 | T23: {=SUMIF(E21:E26,$O23,F21:F26)+SUMIF(H21:H26,$O23,G21:G26)} -> 0 | U23: {=SUMIF(E21:E26,$O23,G21:G26)+SUMIF(H21:H26,$O23,F21:F26)} -> 9 | V23: {=P23*3+Q23*1+BT23+CN23+S23/1000+T23/10000+AV23/1000000+ROW()/10000000} -> -0.0089977 | W23: {=O23} -> Haiti | Y23: {=CONCATENATE("3",RIGHT(E20,1))} -> 3C | Z23: {=VLOOKUP(AL23,V21:W24,2,FALSE)} -> Escocia | AA23: {=SUM(AB23:AD23)} -> 3 | AB23: {=VLOOKUP($Z23,$O$21:$U$24,COLUMN()-26,FALSE)} -> 1 | AC23: {=VLOOKUP($Z23,$O$21:$U$24,COLUMN()-26,FALSE)} -> 0 | AD23: {=VLOOKUP($Z23,$O$21:$U$24,COLUMN()-26,FALSE)} -> 2 | AE23: {=VLOOKUP($Z23,$O$21:$U$24,COLUMN()-26,FALSE)} -> 1 | AF23: {=VLOOKUP($Z23,$O$21:$U$24,COLUMN()-26,FALSE)} -> 5 | AG23: {=VLOOKUP($Z23,$O$21:$U$24,COLUMN()-26,FALSE)} -> 4 | AH23: {=VLOOKUP($Z23,$O$21:$V$24,COLUMN()-26,FALSE)} -> 3.0015024 | AI23: {=(COUNTIFS($CV$2:$CV$13,Z23,$CX$2:$CX$13,"IN")+COUNTIFS($CV$2:$CV$13,Z23,$CW$2:$CW$13,"IN"))*IF(SUM(AA21:AA24)=12,1,0)} -> 1 | AL23: {=LARGE(V21:V24,3)} -> 3.0015024 | AM23: {=(AH23-AL23)*100000000000000000000} -> 0 | AP23: {=O23} -> Haiti | AQ23: {=P23*3+Q23*1+BT23+CN23+S23/1000+T23/10000} -> -0.009 | AR23: {=IF(OR(AQ23=AQ24),1)} -> FALSE | AS23: {=AV23} -> 0 | AT23: {=IF(AND(AM25="si",OR(AR21=1,AR22=1,AR23=1)),1,0)} -> 0 | AU23: {=O23} -> Haiti | AX23: {=Y20} -> Grupo C | AY23: {=O23} -> Haiti | AZ23: {=P23*3+Q23} -> 0 | BA23: {=COUNTIFS($AX$1:AX23,AX23,$AZ$1:AZ23,AZ23)} -> 1 | BB23: {=IF(AZ23=BF19,ROW()*0.001,AZ23)} -> 0 | BC23: {=COUNTIFS($AX$1:AZ23,AZ23,$AZ$1:BB23,BB23)} -> 2 | BE23: {=IF(OR(BF23="-",BI23="-",BF19=0),"-","OK")} -> - | BF23: {=IF(_xlfn.XLOOKUP($E23,$AY1:$AY108,$AZ1:$AZ108,"-",0)=BF19,$E23,"-")} -> - | BG23: {=$F23} -> 3 | BH23: {=$G23} -> 0 | BI23: {=IF(_xlfn.XLOOKUP($H23,$AY1:$AY108,$AZ1:$AZ108,"-",0)=BF19,$H23,"-")} -> - | BK23: {=O23} -> Haiti | BL23: {=COUNTIFS($BE1:$BE108,"OK",$BI1:$BI108,BK23)+COUNTIFS($BE1:$BE108,"OK",$BF1:$BF108,BK23)} -> 0 | BM23: {=COUNTIFS(J1:J108,$BK23,$BE1:$BE108,"OK")} -> 0 | BN23: {=COUNTIFS(K1:K108,$BK23,$BE1:$BE108,"OK")+COUNTIFS(L1:L108,$BK23,$BE1:$BE108,"OK")} -> 0 | BO23: {=COUNTIFS(M1:M108,$BK23,$BE1:$BE108,"OK")} -> 0 | BP23: {=BQ23-BR23} -> 0 | BQ23: {=SUMIFS(BG1:BG108,$BE1:$BE108,"OK",BF1:BF108,$BK23)+SUMIFS(BH1:BH108,$BE1:$BE108,"OK",BI1:BI108,$BK23)} -> 0 | BR23: {=SUMIFS(BH1:BH108,$BE1:$BE108,"OK",BF1:BF108,$BK23)+SUMIFS(BG1:BG108,$BE1:$BE108,"OK",BI1:BI108,$BK23)} -> 0 | BS23: {=BM23*3+BN23*1+BP23/100+BQ23/10000} -> 0 | BT23: {=IF(BL23=0,0,_xlfn.XLOOKUP(BS23,BV21:BV24,BW21:BW24))} -> 0 | BV23: {=LARGE(BS21:BS24,3)} -> 0 | BW23: {=BX23/$BW$1} -> 0.1 | BX23: 1 | BY23: {=IF(OR(BZ23="-",CC23="-"),"-","OK")} -> - | BZ23: {=IF(_xlfn.XLOOKUP($E23,$AY1:$AY108,$AZ1:$AZ108,"-",0)=BZ19,$E23,"-")} -> Brasil | CA23: {=$F23} -> 3 | CB23: {=$G23} -> 0 | CC23: {=IF(_xlfn.XLOOKUP($H23,$AY1:$AY108,$AZ1:$AZ108,"-",0)=BZ19,$H23,"-")} -> - | CE23: {=BK23} -> Haiti | CF23: {=COUNTIFS($BY1:$BY108,"OK",$CC1:$CC108,CE23)+COUNTIFS($BY1:$BY108,"OK",$BZ1:$BZ108,CE23)} -> 0 | CG23: {=COUNTIFS(P1:P108,$BK23,$BY1:$BY108,"OK")} -> 0 | CH23: {=COUNTIFS(K1:K108,$BK23,$BY1:$BY108,"OK")+COUNTIFS(L1:L108,$BK23,$BY1:$BY108,"OK")} -> 0 | CI23: {=COUNTIFS(M1:M108,$CE23,$BY1:$BY108,"OK")} -> 0 | CJ23: {=CK23-CL23} -> 0 | CK23: {=SUMIFS(CA1:CA108,$BY1:$BY108,"OK",BZ1:BZ108,$BK23)+SUMIFS(CB1:CB108,$BY1:$BY108,"OK",CC1:CC108,$BK23)} -> 0 | CL23: {=SUMIFS(CB1:CB108,$BY1:$BY108,"OK",BZ1:BZ108,$BK23)+SUMIFS(CA1:CA108,$BY1:$BY108,"OK",CC1:CC108,$BK23)} -> 0 | CM23: {=CG23*3+CH23*1+CJ23/100+CK23/10000} -> 0 | CN23: {=IF(CF23=0,0,_xlfn.XLOOKUP(CM23,CP21:CP24,CQ21:CQ24))} -> 0 | CP23: {=LARGE(CM21:CM24,3)} -> 0 | CQ23: {=CR23/$BW$1} -> 0.1 | CR23: 1
